Workbook

Sheet Score Board
B3: Player | C3: Callum | D3: Charlotte | E3: Ellena | F3: George | G3: Harry | H3: Nicola | I3: Reece | J3: Rory | K3: Ruby | L3: Sam A | M3: Sam L | N3: Will | O3: Caius
B4: GW1 | C4: {=IF(INDIRECT("Sheet2!D" & 9 + (ROW(C4)-ROW($C$4))*7)=0, "", INDIRECT("Sheet2!D" & 9 + (ROW(C4)-ROW($C$4))*7))} | D4: {=IF(INDIRECT("Sheet2!E" & 9 + (ROW(D4)-ROW($C$4))*7)=0, "", INDIRECT("Sheet2!E" & 9 + (ROW(D4)-ROW($C$4))*7))} | E4: {=IF(INDIRECT("Sheet2!F" & 9 + (ROW(E4)-ROW($C$4))*7)=0, "", INDIRECT("Sheet2!F" & 9 + (ROW(E4)-ROW($C$4))*7))} | F4: {=IF(INDIRECT("Sheet2!G" & 9 + (ROW(F4)-ROW($C$4))*7)=0, "", INDIRECT("Sheet2!G" & 9 + (ROW(F4)-ROW($C$4))*7))} | G4: {=IF(INDIRECT("Sheet2!H" & 9 + (ROW(G4)-ROW($C$4))*7)=0, "", INDIRECT("Sheet2!H" & 9 + (ROW(G4)-ROW($C$4))*7))} | H4: {=IF(INDIRECT("Sheet2!I" & 9 + (ROW(H4)-ROW($C$4))*7)=0, "", INDIRECT("Sheet2!I" & 9 + (ROW(H4)-ROW($C$4))*7))} | I4: {=IF(INDIRECT("Sheet2!J" & 9 + (ROW(I4)-ROW($C$4))*7)=0, "", INDIRECT("Sheet2!J" & 9 + (ROW(I4)-ROW($C$4))*7))} | J4: {=IF(INDIRECT("Sheet2!K" & 9 + (ROW(J4)-ROW($C$4))*7)=0, "", INDIRECT("Sheet2!K" & 9 + (ROW(J4)-ROW($C$4))*7))} | K4: {=IF(INDIRECT("Sheet2!L" & 9 + (ROW(K4)-ROW($C$4))*7)=0, "", INDIRECT("Sheet2!L" & 9 + (ROW(K4)-ROW($C$4))*7))} | L4: {=IF(INDIRECT("Sheet2!M" & 9 + (ROW(L4)-ROW($C$4))*7)=0, "", INDIRECT("Sheet2!M" & 9 + (ROW(L4)-ROW($C$4))*7))} | M4: {=IF(INDIRECT("Sheet2!N" & 9 + (ROW(M4)-ROW($C$4))*7)=0, "", INDIRECT("Sheet2!N" & 9 + (ROW(M4)-ROW($C$4))*7))} | N4: {=IF(INDIRECT("Sheet2!O" & 9 + (ROW(O4)-ROW($C$4))*7)=0, "", INDIRECT("Sheet2!O" & 9 + (ROW(O4)-ROW($C$4))*7))} | O4: {=IF(INDIRECT("Sheet2!P" & 9 + (ROW(P4)-ROW($C$4))*7)=0, "", INDIRECT("Sheet2!P" & 9 + (ROW(P4)-ROW($C$4))*7))}
B5: GW2 | C5: {=IF(INDIRECT("Sheet2!D" & 9 + (ROW(C5)-ROW($C$4))*7)=0, "", INDIRECT("Sheet2!D" & 9 + (ROW(C5)-ROW($C$4))*7))} | D5: {=IF(INDIRECT("Sheet2!E" & 9 + (ROW(D5)-ROW($C$4))*7)=0, "", INDIRECT("Sheet2!E" & 9 + (ROW(D5)-ROW($C$4))*7))} | E5: {=IF(INDIRECT("Sheet2!F" & 9 + (ROW(E5)-ROW($C$4))*7)=0, "", INDIRECT("Sheet2!F" & 9 + (ROW(E5)-ROW($C$4))*7))} | F5: {=IF(INDIRECT("Sheet2!G" & 9 + (ROW(F5)-ROW($C$4))*7)=0, "", INDIRECT("Sheet2!G" & 9 + (ROW(F5)-ROW($C$4))*7))} | G5: {=IF(INDIRECT("Sheet2!H" & 9 + (ROW(G5)-ROW($C$4))*7)=0, "", INDIRECT("Sheet2!H" & 9 + (ROW(G5)-ROW($C$4))*7))} | H5: {=IF(INDIRECT("Sheet2!I" & 9 + (ROW(H5)-ROW($C$4))*7)=0, "", INDIRECT("Sheet2!I" & 9 + (ROW(H5)-ROW($C$4))*7))} | I5: {=IF(INDIRECT("Sheet2!J" & 9 + (ROW(I5)-ROW($C$4))*7)=0, "", INDIRECT("Sheet2!J" & 9 + (ROW(I5)-ROW($C$4))*7))} | J5: {=IF(INDIRECT("Sheet2!K" & 9 + (ROW(J5)-ROW($C$4))*7)=0, "", INDIRECT("Sheet2!K" & 9 + (ROW(J5)-ROW($C$4))*7))} | K5: {=IF(INDIRECT("Sheet2!L" & 9 + (ROW(K5)-ROW($C$4))*7)=0, "", INDIRECT("Sheet2!L" & 9 + (ROW(K5)-ROW($C$4))*7))} | L5: {=IF(INDIRECT("Sheet2!M" & 9 + (ROW(L5)-ROW($C$4))*7)=0, "", INDIRECT("Sheet2!M" & 9 + (ROW(L5)-ROW($C$4))*7))} | M5: {=IF(INDIRECT("Sheet2!N" & 9 + (ROW(M5)-ROW($C$4))*7)=0, "", INDIRECT("Sheet2!N" & 9 + (ROW(M5)-ROW($C$4))*7))} | N5: {=IF(INDIRECT("Sheet2!O" & 9 + (ROW(O5)-ROW($C$4))*7)=0, "", INDIRECT("Sheet2!O" & 9 + (ROW(O5)-ROW($C$4))*7))} | O5: {=IF(INDIRECT("Sheet2!P" & 9 + (ROW(P5)-ROW($C$4))*7)=0, "", INDIRECT("Sheet2!P" & 9 + (ROW(P5)-ROW($C$4))*7))}
B6: GW3 | C6: {=IF(INDIRECT("Sheet2!D" & 9 + (ROW(C6)-ROW($C$4))*7)=0, "", INDIRECT("Sheet2!D" & 9 + (ROW(C6)-ROW($C$4))*7))} | D6: {=IF(INDIRECT("Sheet2!E" & 9 + (ROW(D6)-ROW($C$4))*7)=0, "", INDIRECT("Sheet2!E" & 9 + (ROW(D6)-ROW($C$4))*7))} | E6: {=IF(INDIRECT("Sheet2!F" & 9 + (ROW(E6)-ROW($C$4))*7)=0, "", INDIRECT("Sheet2!F" & 9 + (ROW(E6)-ROW($C$4))*7))} | F6: {=IF(INDIRECT("Sheet2!G" & 9 + (ROW(F6)-ROW($C$4))*7)=0, "", INDIRECT("Sheet2!G" & 9 + (ROW(F6)-ROW($C$4))*7))} | G6: {=IF(INDIRECT("Sheet2!H" & 9 + (ROW(G6)-ROW($C$4))*7)=0, "", INDIRECT("Sheet2!H" & 9 + (ROW(G6)-ROW($C$4))*7))} | H6: {=IF(INDIRECT("Sheet2!I" & 9 + (ROW(H6)-ROW($C$4))*7)=0, "", INDIRECT("Sheet2!I" & 9 + (ROW(H6)-ROW($C$4))*7))} | I6: {=IF(INDIRECT("Sheet2!J" & 9 + (ROW(I6)-ROW($C$4))*7)=0, "", INDIRECT("Sheet2!J" & 9 + (ROW(I6)-ROW($C$4))*7))} | J6: {=IF(INDIRECT("Sheet2!K" & 9 + (ROW(J6)-ROW($C$4))*7)=0, "", INDIRECT("Sheet2!K" & 9 + (ROW(J6)-ROW($C$4))*7))} | K6: {=IF(INDIRECT("Sheet2!L" & 9 + (ROW(K6)-ROW($C$4))*7)=0, "", INDIRECT("Sheet2!L" & 9 + (ROW(K6)-ROW($C$4))*7))} | L6: {=IF(INDIRECT("Sheet2!M" & 9 + (ROW(L6)-ROW($C$4))*7)=0, "", INDIRECT("Sheet2!M" & 9 + (ROW(L6)-ROW($C$4))*7))} | M6: {=IF(INDIRECT("Sheet2!N" & 9 + (ROW(M6)-ROW($C$4))*7)=0, "", INDIRECT("Sheet2!N" & 9 + (ROW(M6)-ROW($C$4))*7))} | N6: {=IF(INDIRECT("Sheet2!O" & 9 + (ROW(O6)-ROW($C$4))*7)=0, "", INDIRECT("Sheet2!O" & 9 + (ROW(O6)-ROW($C$4))*7))} | O6: {=IF(INDIRECT("Sheet2!P" & 9 + (ROW(P6)-ROW($C$4))*7)=0, "", INDIRECT("Sheet2!P" & 9 + (ROW(P6)-ROW($C$4))*7))}
B7: GW4 | C7: {=IF(INDIRECT("Sheet2!D" & 9 + (ROW(C7)-ROW($C$4))*7)=0, "", INDIRECT("Sheet2!D" & 9 + (ROW(C7)-ROW($C$4))*7))} | D7: {=IF(INDIRECT("Sheet2!E" & 9 + (ROW(D7)-ROW($C$4))*7)=0, "", INDIRECT("Sheet2!E" & 9 + (ROW(D7)-ROW($C$4))*7))} | E7: {=IF(INDIRECT("Sheet2!F" & 9 + (ROW(E7)-ROW($C$4))*7)=0, "", INDIRECT("Sheet2!F" & 9 + (ROW(E7)-ROW($C$4))*7))} | F7: {=IF(INDIRECT("Sheet2!G" & 9 + (ROW(F7)-ROW($C$4))*7)=0, "", INDIRECT("Sheet2!G" & 9 + (ROW(F7)-ROW($C$4))*7))} | G7: {=IF(INDIRECT("Sheet2!H" & 9 + (ROW(G7)-ROW($C$4))*7)=0, "", INDIRECT("Sheet2!H" & 9 + (ROW(G7)-ROW($C$4))*7))} | H7: {=IF(INDIRECT("Sheet2!I" & 9 + (ROW(H7)-ROW($C$4))*7)=0, "", INDIRECT("Sheet2!I" & 9 + (ROW(H7)-ROW($C$4))*7))} | I7: {=IF(INDIRECT("Sheet2!J" & 9 + (ROW(I7)-ROW($C$4))*7)=0, "", INDIRECT("Sheet2!J" & 9 + (ROW(I7)-ROW($C$4))*7))} | J7: {=IF(INDIRECT("Sheet2!K" & 9 + (ROW(J7)-ROW($C$4))*7)=0, "", INDIRECT("Sheet2!K" & 9 + (ROW(J7)-ROW($C$4))*7))} | K7: {=IF(INDIRECT("Sheet2!L" & 9 + (ROW(K7)-ROW($C$4))*7)=0, "", INDIRECT("Sheet2!L" & 9 + (ROW(K7)-ROW($C$4))*7))} | L7: {=IF(INDIRECT("Sheet2!M" & 9 + (ROW(L7)-ROW($C$4))*7)=0, "", INDIRECT("Sheet2!M" & 9 + (ROW(L7)-ROW($C$4))*7))} | M7: {=IF(INDIRECT("Sheet2!N" & 9 + (ROW(M7)-ROW($C$4))*7)=0, "", INDIRECT("Sheet2!N" & 9 + (ROW(M7)-ROW($C$4))*7))} | N7: {=IF(INDIRECT("Sheet2!O" & 9 + (ROW(O7)-ROW($C$4))*7)=0, "", INDIRECT("Sheet2!O" & 9 + (ROW(O7)-ROW($C$4))*7))} | O7: {=IF(INDIRECT("Sheet2!P" & 9 + (ROW(P7)-ROW($C$4))*7)=0, "", INDIRECT("Sheet2!P" & 9 + (ROW(P7)-ROW($C$4))*7))}
B8: GW5 | C8: {=IF(INDIRECT("Sheet2!D" & 9 + (ROW(C8)-ROW($C$4))*7)=0, "", INDIRECT("Sheet2!D" & 9 + (ROW(C8)-ROW($C$4))*7))} | D8: {=IF(INDIRECT("Sheet2!E" & 9 + (ROW(D8)-ROW($C$4))*7)=0, "", INDIRECT("Sheet2!E" & 9 + (ROW(D8)-ROW($C$4))*7))} | E8: {=IF(INDIRECT("Sheet2!F" & 9 + (ROW(E8)-ROW($C$4))*7)=0, "", INDIRECT("Sheet2!F" & 9 + (ROW(E8)-ROW($C$4))*7))} | F8: {=IF(INDIRECT("Sheet2!G" & 9 + (ROW(F8)-ROW($C$4))*7)=0, "", INDIRECT("Sheet2!G" & 9 + (ROW(F8)-ROW($C$4))*7))} | G8: {=IF(INDIRECT("Sheet2!H" & 9 + (ROW(G8)-ROW($C$4))*7)=0, "", INDIRECT("Sheet2!H" & 9 + (ROW(G8)-ROW($C$4))*7))} | H8: {=IF(INDIRECT("Sheet2!I" & 9 + (ROW(H8)-ROW($C$4))*7)=0, "", INDIRECT("Sheet2!I" & 9 + (ROW(H8)-ROW($C$4))*7))} | I8: {=IF(INDIRECT("Sheet2!J" & 9 + (ROW(I8)-ROW($C$4))*7)=0, "", INDIRECT("Sheet2!J" & 9 + (ROW(I8)-ROW($C$4))*7))} | J8: {=IF(INDIRECT("Sheet2!K" & 9 + (ROW(J8)-ROW($C$4))*7)=0, "", INDIRECT("Sheet2!K" & 9 + (ROW(J8)-ROW($C$4))*7))} | K8: {=IF(INDIRECT("Sheet2!L" & 9 + (ROW(K8)-ROW($C$4))*7)=0, "", INDIRECT("Sheet2!L" & 9 + (ROW(K8)-ROW($C$4))*7))} | L8: {=IF(INDIRECT("Sheet2!M" & 9 + (ROW(L8)-ROW($C$4))*7)=0, "", INDIRECT("Sheet2!M" & 9 + (ROW(L8)-ROW($C$4))*7))} | M8: {=IF(INDIRECT("Sheet2!N" & 9 + (ROW(M8)-ROW($C$4))*7)=0, "", INDIRECT("Sheet2!N" & 9 + (ROW(M8)-ROW($C$4))*7))} | N8: {=IF(INDIRECT("Sheet2!O" & 9 + (ROW(O8)-ROW($C$4))*7)=0, "", INDIRECT("Sheet2!O" & 9 + (ROW(O8)-ROW($C$4))*7))} | O8: {=IF(INDIRECT("Sheet2!P" & 9 + (ROW(P8)-ROW($C$4))*7)=0, "", INDIRECT("Sheet2!P" & 9 + (ROW(P8)-ROW($C$4))*7))}
B9: GW6 | C9: {=IF(INDIRECT("Sheet2!D" & 9 + (ROW(C9)-ROW($C$4))*7)=0, "", INDIRECT("Sheet2!D" & 9 + (ROW(C9)-ROW($C$4))*7))} | D9: {=IF(INDIRECT("Sheet2!E" & 9 + (ROW(D9)-ROW($C$4))*7)=0, "", INDIRECT("Sheet2!E" & 9 + (ROW(D9)-ROW($C$4))*7))} | E9: {=IF(INDIRECT("Sheet2!F" & 9 + (ROW(E9)-ROW($C$4))*7)=0, "", INDIRECT("Sheet2!F" & 9 + (ROW(E9)-ROW($C$4))*7))} | F9: {=IF(INDIRECT("Sheet2!G" & 9 + (ROW(F9)-ROW($C$4))*7)=0, "", INDIRECT("Sheet2!G" & 9 + (ROW(F9)-ROW($C$4))*7))} | G9: {=IF(INDIRECT("Sheet2!H" & 9 + (ROW(G9)-ROW($C$4))*7)=0, "", INDIRECT("Sheet2!H" & 9 + (ROW(G9)-ROW($C$4))*7))} | H9: {=IF(INDIRECT("Sheet2!I" & 9 + (ROW(H9)-ROW($C$4))*7)=0, "", INDIRECT("Sheet2!I" & 9 + (ROW(H9)-ROW($C$4))*7))} | I9: {=IF(INDIRECT("Sheet2!J" & 9 + (ROW(I9)-ROW($C$4))*7)=0, "", INDIRECT("Sheet2!J" & 9 + (ROW(I9)-ROW($C$4))*7))} | J9: {=IF(INDIRECT("Sheet2!K" & 9 + (ROW(J9)-ROW($C$4))*7)=0, "", INDIRECT("Sheet2!K" & 9 + (ROW(J9)-ROW($C$4))*7))} | K9: {=IF(INDIRECT("Sheet2!L" & 9 + (ROW(K9)-ROW($C$4))*7)=0, "", INDIRECT("Sheet2!L" & 9 + (ROW(K9)-ROW($C$4))*7))} | L9: {=IF(INDIRECT("Sheet2!M" & 9 + (ROW(L9)-ROW($C$4))*7)=0, "", INDIRECT("Sheet2!M" & 9 + (ROW(L9)-ROW($C$4))*7))} | M9: {=IF(INDIRECT("Sheet2!N" & 9 + (ROW(M9)-ROW($C$4))*7)=0, "", INDIRECT("Sheet2!N" & 9 + (ROW(M9)-ROW($C$4))*7))} | N9: {=IF(INDIRECT("Sheet2!O" & 9 + (ROW(O9)-ROW($C$4))*7)=0, "", INDIRECT("Sheet2!O" & 9 + (ROW(O9)-ROW($C$4))*7))} | O9: {=IF(INDIRECT("Sheet2!P" & 9 + (ROW(P9)-ROW($C$4))*7)=0, "", INDIRECT("Sheet2!P" & 9 + (ROW(P9)-ROW($C$4))*7))}
B10: GW7 | C10: {=IF(INDIRECT("Sheet2!D" & 9 + (ROW(C10)-ROW($C$4))*7)=0, "", INDIRECT("Sheet2!D" & 9 + (ROW(C10)-ROW($C$4))*7))} | D10: {=IF(INDIRECT("Sheet2!E" & 9 + (ROW(D10)-ROW($C$4))*7)=0, "", INDIRECT("Sheet2!E" & 9 + (ROW(D10)-ROW($C$4))*7))} | E10: {=IF(INDIRECT("Sheet2!F" & 9 + (ROW(E10)-ROW($C$4))*7)=0, "", INDIRECT("Sheet2!F" & 9 + (ROW(E10)-ROW($C$4))*7))} | F10: {=IF(INDIRECT("Sheet2!G" & 9 + (ROW(F10)-ROW($C$4))*7)=0, "", INDIRECT("Sheet2!G" & 9 + (ROW(F10)-ROW($C$4))*7))} | G10: {=IF(INDIRECT("Sheet2!H" & 9 + (ROW(G10)-ROW($C$4))*7)=0, "", INDIRECT("Sheet2!H" & 9 + (ROW(G10)-ROW($C$4))*7))} | H10: {=IF(INDIRECT("Sheet2!I" & 9 + (ROW(H10)-ROW($C$4))*7)=0, "", INDIRECT("Sheet2!I" & 9 + (ROW(H10)-ROW($C$4))*7))} | I10: {=IF(INDIRECT("Sheet2!J" & 9 + (ROW(I10)-ROW($C$4))*7)=0, "", INDIRECT("Sheet2!J" & 9 + (ROW(I10)-ROW($C$4))*7))} | J10: {=IF(INDIRECT("Sheet2!K" & 9 + (ROW(J10)-ROW($C$4))*7)=0, "", INDIRECT("Sheet2!K" & 9 + (ROW(J10)-ROW($C$4))*7))} | K10: {=IF(INDIRECT("Sheet2!L" & 9 + (ROW(K10)-ROW($C$4))*7)=0, "", INDIRECT("Sheet2!L" & 9 + (ROW(K10)-ROW($C$4))*7))} | L10: {=IF(INDIRECT("Sheet2!M" & 9 + (ROW(L10)-ROW($C$4))*7)=0, "", INDIRECT("Sheet2!M" & 9 + (ROW(L10)-ROW($C$4))*7))} | M10: {=IF(INDIRECT("Sheet2!N" & 9 + (ROW(M10)-ROW($C$4))*7)=0, "", INDIRECT("Sheet2!N" & 9 + (ROW(M10)-ROW($C$4))*7))} | N10: {=IF(INDIRECT("Sheet2!O" & 9 + (ROW(O10)-ROW($C$4))*7)=0, "", INDIRECT("Sheet2!O" & 9 + (ROW(O10)-ROW($C$4))*7))} | O10: {=IF(INDIRECT("Sheet2!P" & 9 + (ROW(P10)-ROW($C$4))*7)=0, "", INDIRECT("Sheet2!P" & 9 + (ROW(P10)-ROW($C$4))*7))}
B11: GW8 | C11: {=IF(INDIRECT("Sheet2!D" & 9 + (ROW(C11)-ROW($C$4))*7)=0, "", INDIRECT("Sheet2!D" & 9 + (ROW(C11)-ROW($C$4))*7))} | D11: {=IF(INDIRECT("Sheet2!E" & 9 + (ROW(D11)-ROW($C$4))*7)=0, "", INDIRECT("Sheet2!E" & 9 + (ROW(D11)-ROW($C$4))*7))} | E11: {=IF(INDIRECT("Sheet2!F" & 9 + (ROW(E11)-ROW($C$4))*7)=0, "", INDIRECT("Sheet2!F" & 9 + (ROW(E11)-ROW($C$4))*7))} | F11: {=IF(INDIRECT("Sheet2!G" & 9 + (ROW(F11)-ROW($C$4))*7)=0, "", INDIRECT("Sheet2!G" & 9 + (ROW(F11)-ROW($C$4))*7))} | G11: {=IF(INDIRECT("Sheet2!H" & 9 + (ROW(G11)-ROW($C$4))*7)=0, "", INDIRECT("Sheet2!H" & 9 + (ROW(G11)-ROW($C$4))*7))} | H11: {=IF(INDIRECT("Sheet2!I" & 9 + (ROW(H11)-ROW($C$4))*7)=0, "", INDIRECT("Sheet2!I" & 9 + (ROW(H11)-ROW($C$4))*7))} | I11: {=IF(INDIRECT("Sheet2!J" & 9 + (ROW(I11)-ROW($C$4))*7)=0, "", INDIRECT("Sheet2!J" & 9 + (ROW(I11)-ROW($C$4))*7))} | J11: {=IF(INDIRECT("Sheet2!K" & 9 + (ROW(J11)-ROW($C$4))*7)=0, "", INDIRECT("Sheet2!K" & 9 + (ROW(J11)-ROW($C$4))*7))} | K11: {=IF(INDIRECT("Sheet2!L" & 9 + (ROW(K11)-ROW($C$4))*7)=0, "", INDIRECT("Sheet2!L" & 9 + (ROW(K11)-ROW($C$4))*7))} | L11: {=IF(INDIRECT("Sheet2!M" & 9 + (ROW(L11)-ROW($C$4))*7)=0, "", INDIRECT("Sheet2!M" & 9 + (ROW(L11)-ROW($C$4))*7))} | M11: {=IF(INDIRECT("Sheet2!N" & 9 + (ROW(M11)-ROW($C$4))*7)=0, "", INDIRECT("Sheet2!N" & 9 + (ROW(M11)-ROW($C$4))*7))} | N11: {=IF(INDIRECT("Sheet2!O" & 9 + (ROW(O11)-ROW($C$4))*7)=0, "", INDIRECT("Sheet2!O" & 9 + (ROW(O11)-ROW($C$4))*7))} | O11: {=IF(INDIRECT("Sheet2!P" & 9 + (ROW(P11)-ROW($C$4))*7)=0, "", INDIRECT("Sheet2!P" & 9 + (ROW(P11)-ROW($C$4))*7))}
B12: GW9 | C12: {=IF(INDIRECT("Sheet2!D" & 9 + (ROW(C12)-ROW($C$4))*7)=0, "", INDIRECT("Sheet2!D" & 9 + (ROW(C12)-ROW($C$4))*7))} | D12: {=IF(INDIRECT("Sheet2!E" & 9 + (ROW(D12)-ROW($C$4))*7)=0, "", INDIRECT("Sheet2!E" & 9 + (ROW(D12)-ROW($C$4))*7))} | E12: {=IF(INDIRECT("Sheet2!F" & 9 + (ROW(E12)-ROW($C$4))*7)=0, "", INDIRECT("Sheet2!F" & 9 + (ROW(E12)-ROW($C$4))*7))} | F12: {=IF(INDIRECT("Sheet2!G" & 9 + (ROW(F12)-ROW($C$4))*7)=0, "", INDIRECT("Sheet2!G" & 9 + (ROW(F12)-ROW($C$4))*7))} | G12: {=IF(INDIRECT("Sheet2!H" & 9 + (ROW(G12)-ROW($C$4))*7)=0, "", INDIRECT("Sheet2!H" & 9 + (ROW(G12)-ROW($C$4))*7))} | H12: {=IF(INDIRECT("Sheet2!I" & 9 + (ROW(H12)-ROW($C$4))*7)=0, "", INDIRECT("Sheet2!I" & 9 + (ROW(H12)-ROW($C$4))*7))} | I12: {=IF(INDIRECT("Sheet2!J" & 9 + (ROW(I12)-ROW($C$4))*7)=0, "", INDIRECT("Sheet2!J" & 9 + (ROW(I12)-ROW($C$4))*7))} | J12: {=IF(INDIRECT("Sheet2!K" & 9 + (ROW(J12)-ROW($C$4))*7)=0, "", INDIRECT("Sheet2!K" & 9 + (ROW(J12)-ROW($C$4))*7))} | K12: {=IF(INDIRECT("Sheet2!L" & 9 + (ROW(K12)-ROW($C$4))*7)=0, "", INDIRECT("Sheet2!L" & 9 + (ROW(K12)-ROW($C$4))*7))} | L12: {=IF(INDIRECT("Sheet2!M" & 9 + (ROW(L12)-ROW($C$4))*7)=0, "", INDIRECT("Sheet2!M" & 9 + (ROW(L12)-ROW($C$4))*7))} | M12: {=IF(INDIRECT("Sheet2!N" & 9 + (ROW(M12)-ROW($C$4))*7)=0, "", INDIRECT("Sheet2!N" & 9 + (ROW(M12)-ROW($C$4))*7))} | N12: {=IF(INDIRECT("Sheet2!O" & 9 + (ROW(O12)-ROW($C$4))*7)=0, "", INDIRECT("Sheet2!O" & 9 + (ROW(O12)-ROW($C$4))*7))} | O12: {=IF(INDIRECT("Sheet2!P" & 9 + (ROW(P12)-ROW($C$4))*7)=0, "", INDIRECT("Sheet2!P" & 9 + (ROW(P12)-ROW($C$4))*7))}
B13: GW10 | C13: {=IF(INDIRECT("Sheet2!D" & 9 + (ROW(C13)-ROW($C$4))*7)=0, "", INDIRECT("Sheet2!D" & 9 + (ROW(C13)-ROW($C$4))*7))} | D13: {=IF(INDIRECT("Sheet2!E" & 9 + (ROW(D13)-ROW($C$4))*7)=0, "", INDIRECT("Sheet2!E" & 9 + (ROW(D13)-ROW($C$4))*7))} | E13: {=IF(INDIRECT("Sheet2!F" & 9 + (ROW(E13)-ROW($C$4))*7)=0, "", INDIRECT("Sheet2!F" & 9 + (ROW(E13)-ROW($C$4))*7))} | F13: {=IF(INDIRECT("Sheet2!G" & 9 + (ROW(F13)-ROW($C$4))*7)=0, "", INDIRECT("Sheet2!G" & 9 + (ROW(F13)-ROW($C$4))*7))} | G13: {=IF(INDIRECT("Sheet2!H" & 9 + (ROW(G13)-ROW($C$4))*7)=0, "", INDIRECT("Sheet2!H" & 9 + (ROW(G13)-ROW($C$4))*7))} | H13: {=IF(INDIRECT("Sheet2!I" & 9 + (ROW(H13)-ROW($C$4))*7)=0, "", INDIRECT("Sheet2!I" & 9 + (ROW(H13)-ROW($C$4))*7))} | I13: {=IF(INDIRECT("Sheet2!J" & 9 + (ROW(I13)-ROW($C$4))*7)=0, "", INDIRECT("Sheet2!J" & 9 + (ROW(I13)-ROW($C$4))*7))} | J13: {=IF(INDIRECT("Sheet2!K" & 9 + (ROW(J13)-ROW($C$4))*7)=0, "", INDIRECT("Sheet2!K" & 9 + (ROW(J13)-ROW($C$4))*7))} | K13: {=IF(INDIRECT("Sheet2!L" & 9 + (ROW(K13)-ROW($C$4))*7)=0, "", INDIRECT("Sheet2!L" & 9 + (ROW(K13)-ROW($C$4))*7))} | L13: {=IF(INDIRECT("Sheet2!M" & 9 + (ROW(L13)-ROW($C$4))*7)=0, "", INDIRECT("Sheet2!M" & 9 + (ROW(L13)-ROW($C$4))*7))} | M13: {=IF(INDIRECT("Sheet2!N" & 9 + (ROW(M13)-ROW($C$4))*7)=0, "", INDIRECT("Sheet2!N" & 9 + (ROW(M13)-ROW($C$4))*7))} | N13: {=IF(INDIRECT("Sheet2!O" & 9 + (ROW(O13)-ROW($C$4))*7)=0, "", INDIRECT("Sheet2!O" & 9 + (ROW(O13)-ROW($C$4))*7))} | O13: {=IF(INDIRECT("Sheet2!P" & 9 + (ROW(P13)-ROW($C$4))*7)=0, "", INDIRECT("Sheet2!P" & 9 + (ROW(P13)-ROW($C$4))*7))}
B14: GW11 | C14: {=IF(INDIRECT("Sheet2!D" & 9 + (ROW(C14)-ROW($C$4))*7)=0, "", INDIRECT("Sheet2!D" & 9 + (ROW(C14)-ROW($C$4))*7))} | D14: {=IF(INDIRECT("Sheet2!E" & 9 + (ROW(D14)-ROW($C$4))*7)=0, "", INDIRECT("Sheet2!E" & 9 + (ROW(D14)-ROW($C$4))*7))} | E14: {=IF(INDIRECT("Sheet2!F" & 9 + (ROW(E14)-ROW($C$4))*7)=0, "", INDIRECT("Sheet2!F" & 9 + (ROW(E14)-ROW($C$4))*7))} | F14: {=IF(INDIRECT("Sheet2!G" & 9 + (ROW(F14)-ROW($C$4))*7)=0, "", INDIRECT("Sheet2!G" & 9 + (ROW(F14)-ROW($C$4))*7))} | G14: {=IF(INDIRECT("Sheet2!H" & 9 + (ROW(G14)-ROW($C$4))*7)=0, "", INDIRECT("Sheet2!H" & 9 + (ROW(G14)-ROW($C$4))*7))} | H14: {=IF(INDIRECT("Sheet2!I" & 9 + (ROW(H14)-ROW($C$4))*7)=0, "", INDIRECT("Sheet2!I" & 9 + (ROW(H14)-ROW($C$4))*7))} | I14: {=IF(INDIRECT("Sheet2!J" & 9 + (ROW(I14)-ROW($C$4))*7)=0, "", INDIRECT("Sheet2!J" & 9 + (ROW(I14)-ROW($C$4))*7))} | J14: {=IF(INDIRECT("Sheet2!K" & 9 + (ROW(J14)-ROW($C$4))*7)=0, "", INDIRECT("Sheet2!K" & 9 + (ROW(J14)-ROW($C$4))*7))} | K14: {=IF(INDIRECT("Sheet2!L" & 9 + (ROW(K14)-ROW($C$4))*7)=0, "", INDIRECT("Sheet2!L" & 9 + (ROW(K14)-ROW($C$4))*7))} | L14: {=IF(INDIRECT("Sheet2!M" & 9 + (ROW(L14)-ROW($C$4))*7)=0, "", INDIRECT("Sheet2!M" & 9 + (ROW(L14)-ROW($C$4))*7))} | M14: {=IF(INDIRECT("Sheet2!N" & 9 + (ROW(M14)-ROW($C$4))*7)=0, "", INDIRECT("Sheet2!N" & 9 + (ROW(M14)-ROW($C$4))*7))} | N14: {=IF(INDIRECT("Sheet2!O" & 9 + (ROW(O14)-ROW($C$4))*7)=0, "", INDIRECT("Sheet2!O" & 9 + (ROW(O14)-ROW($C$4))*7))} | O14: {=IF(INDIRECT("Sheet2!P" & 9 + (ROW(P14)-ROW($C$4))*7)=0, "", INDIRECT("Sheet2!P" & 9 + (ROW(P14)-ROW($C$4))*7))}
B15: GW12 | C15: {=IF(INDIRECT("Sheet2!D" & 9 + (ROW(C15)-ROW($C$4))*7)=0, "", INDIRECT("Sheet2!D" & 9 + (ROW(C15)-ROW($C$4))*7))} | D15: {=IF(INDIRECT("Sheet2!E" & 9 + (ROW(D15)-ROW($C$4))*7)=0, "", INDIRECT("Sheet2!E" & 9 + (ROW(D15)-ROW($C$4))*7))} | E15: {=IF(INDIRECT("Sheet2!F" & 9 + (ROW(E15)-ROW($C$4))*7)=0, "", INDIRECT("Sheet2!F" & 9 + (ROW(E15)-ROW($C$4))*7))} | F15: {=IF(INDIRECT("Sheet2!G" & 9 + (ROW(F15)-ROW($C$4))*7)=0, "", INDIRECT("Sheet2!G" & 9 + (ROW(F15)-ROW($C$4))*7))} | G15: {=IF(INDIRECT("Sheet2!H" & 9 + (ROW(G15)-ROW($C$4))*7)=0, "", INDIRECT("Sheet2!H" & 9 + (ROW(G15)-ROW($C$4))*7))} | H15: {=IF(INDIRECT("Sheet2!I" & 9 + (ROW(H15)-ROW($C$4))*7)=0, "", INDIRECT("Sheet2!I" & 9 + (ROW(H15)-ROW($C$4))*7))} | I15: {=IF(INDIRECT("Sheet2!J" & 9 + (ROW(I15)-ROW($C$4))*7)=0, "", INDIRECT("Sheet2!J" & 9 + (ROW(I15)-ROW($C$4))*7))} | J15: {=IF(INDIRECT("Sheet2!K" & 9 + (ROW(J15)-ROW($C$4))*7)=0, "", INDIRECT("Sheet2!K" & 9 + (ROW(J15)-ROW($C$4))*7))} | K15: {=IF(INDIRECT("Sheet2!L" & 9 + (ROW(K15)-ROW($C$4))*7)=0, "", INDIRECT("Sheet2!L" & 9 + (ROW(K15)-ROW($C$4))*7))} | L15: {=IF(INDIRECT("Sheet2!M" & 9 + (ROW(L15)-ROW($C$4))*7)=0, "", INDIRECT("Sheet2!M" & 9 + (ROW(L15)-ROW($C$4))*7))} | M15: {=IF(INDIRECT("Sheet2!N" & 9 + (ROW(M15)-ROW($C$4))*7)=0, "", INDIRECT("Sheet2!N" & 9 + (ROW(M15)-ROW($C$4))*7))} | N15: {=IF(INDIRECT("Sheet2!O" & 9 + (ROW(O15)-ROW($C$4))*7)=0, "", INDIRECT("Sheet2!O" & 9 + (ROW(O15)-ROW($C$4))*7))} | O15: {=IF(INDIRECT("Sheet2!P" & 9 + (ROW(P15)-ROW($C$4))*7)=0, "", INDIRECT("Sheet2!P" & 9 + (ROW(P15)-ROW($C$4))*7))}
... B41: GW38 | C41: {=IF(INDIRECT("Sheet2!D" & 9 + (ROW(C41)-ROW($C$4))*7)=0, "", INDIRECT("Sheet2!D" & 9 + (ROW(C41)-ROW($C$4))*7))} | D41: {=IF(INDIRECT("Sheet2!E" & 9 + (ROW(D41)-ROW($C$4))*7)=0, "", INDIRECT("Sheet2!E" & 9 + (ROW(D41)-ROW($C$4))*7))} | E41: {=IF(INDIRECT("Sheet2!F" & 9 + (ROW(E41)-ROW($C$4))*7)=0, "", INDIRECT("Sheet2!F" & 9 + (ROW(E41)-ROW($C$4))*7))} | F41: {=IF(INDIRECT("Sheet2!G" & 9 + (ROW(F41)-ROW($C$4))*7)=0, "", INDIRECT("Sheet2!G" & 9 + (ROW(F41)-ROW($C$4))*7))} | G41: {=IF(INDIRECT("Sheet2!H" & 9 + (ROW(G41)-ROW($C$4))*7)=0, "", INDIRECT("Sheet2!H" & 9 + (ROW(G41)-ROW($C$4))*7))} | H41: {=IF(INDIRECT("Sheet2!I" & 9 + (ROW(H41)-ROW($C$4))*7)=0, "", INDIRECT("Sheet2!I" & 9 + (ROW(H41)-ROW($C$4))*7))} | I41: {=IF(INDIRECT("Sheet2!J" & 9 + (ROW(I41)-ROW($C$4))*7)=0, "", INDIRECT("Sheet2!J" & 9 + (ROW(I41)-ROW($C$4))*7))} | J41: {=IF(INDIRECT("Sheet2!K" & 9 + (ROW(J41)-ROW($C$4))*7)=0, "", INDIRECT("Sheet2!K" & 9 + (ROW(J41)-ROW($C$4))*7))} | K41: {=IF(INDIRECT("Sheet2!L" & 9 + (ROW(K41)-ROW($C$4))*7)=0, "", INDIRECT("Sheet2!L" & 9 + (ROW(K41)-ROW($C$4))*7))} | L41: {=IF(INDIRECT("Sheet2!M" & 9 + (ROW(L41)-ROW($C$4))*7)=0, "", INDIRECT("Sheet2!M" & 9 + (ROW(L41)-ROW($C$4))*7))} | M41: {=IF(INDIRECT("Sheet2!N" & 9 + (ROW(M41)-ROW($C$4))*7)=0, "", INDIRECT("Sheet2!N" & 9 + (ROW(M41)-ROW($C$4))*7))} | N41: {=IF(INDIRECT("Sheet2!O" & 9 + (ROW(O41)-ROW($C$4))*7)=0, "", INDIRECT("Sheet2!O" & 9 + (ROW(O41)-ROW($C$4))*7))} | O41: {=IF(INDIRECT("Sheet2!P" & 9 + (ROW(P41)-ROW($C$4))*7)=0, "", INDIRECT("Sheet2!P" & 9 + (ROW(P41)-ROW($C$4))*7))}
B42: PL Total | C42: =SUM(C4:C41) -> 0 | D42: =SUM(D4:D41) -> 0 | E42: =SUM(E4:E41) -> 0 | F42: =SUM(F4:F41) -> 0 | G42: =SUM(G4:G41) -> 0 | H42: =SUM(H4:H41) -> 0 | I42: =SUM(I4:I41) -> 0 | J42: =SUM(J4:J41) -> 0 | ... O42: =SUM(O4:O41) -> 0
B43: CS | C43: ='Extra Results'!C89 -> 0 | D43: ='Extra Results'!D89 -> 0 | E43: ='Extra Results'!E89 -> 0 | F43: ='Extra Results'!F89 -> 0 | G43: ='Extra Results'!G89 -> 0 | H43: ='Extra Results'!H89 -> 0 | I43: ='Extra Results'!I89 -> 0 | J43: ='Extra Results'!J89 -> 0 | ... O43: ='Extra Results'!O89 -> 0
T50: {=TRANSPOSE(C42:M42)} -> 0
T51: 0
T52: 0
T53: 0
T54: 0
T55: 0
T56: 0
T57: 0
T58: 0
T59: 0
T60: 0

Sheet Sheet2
C1: Match Winner | D1: 1 PT
C2: Correct Score | D2: 3 PTS
R3: EX Purpose
B4: GW1 | D4: Callum | E4: Charlotte | F4: Ellena | G4: George | H4: Harry | I4: Nicola | J4: Reece | K4: Rory | L4: Ruby | M4: Sam A | N4: Sam L | O4: Will | P4: Caius | Q4: EX1 | S4: Callum | T4: Charlotte | U4: Ellena | V4: George | W4: Harry | X4: Nicola | Y4: Reece | Z4: Rory | AA4: Ruby | AB4: Sam A | AC4: Sam L | AD4: Will | AE4: Caius
C9: Total | R9: Total
C10: CS | R10: CS
B11: GW2 | D11: Callum | E11: Charlotte | F11: Ellena | G11: George | H11: Harry | I11: Nicola | J11: Reece | K11: Rory | L11: Ruby | M11: Sam A | N11: Sam L | O11: Will | P11: Caius | Q11: EX2 | S11: Callum | T11: Charlotte | U11: Ellena | V11: George | W11: Harry | X11: Nicola | Y11: Reece | Z11: Rory | AA11: Ruby | AB11: Sam A | AC11: Sam L | AD11: Will | AE11: Caius
C16: Total | R16: Total
C17: CS | R17: CS
B18: GW3 | D18: Callum | E18: Charlotte | F18: Ellena | G18: George | H18: Harry | I18: Nicola | J18: Reece | K18: Rory | L18: Ruby | M18: Sam A | N18: Sam L | O18: Will | P18: Caius | Q18: EX3 | S18: Callum | T18: Charlotte | U18: Ellena | V18: George | W18: Harry | X18: Nicola | Y18: Reece | Z18: Rory | AA18: Ruby | AB18: Sam A | AC18: Sam L | AD18: Will | AE18: Caius
C23: Total | R23: Total
C24: CS | R24: CS
B25: GW4 | D25: Callum | E25: Charlotte | F25: Ellena | G25: George | H25: Harry | I25: Nicola | J25: Reece | K25: Rory | L25: Ruby | M25: Sam A | N25: Sam L | O25: Will | P25: Caius | Q25: EX4 | S25: Callum | T25: Charlotte | U25: Ellena | V25: George | W25: Harry | X25: Nicola | Y25: Reece | Z25: Rory | AA25: Ruby | AB25: Sam A | AC25: Sam L | AD25: Will | AE25: Caius
C30: Total | R30: Total
C31: CS | R31: CS
B32: GW5 | D32: Callum | E32: Charlotte | F32: Ellena | G32: George | H32: Harry | I32: Nicola | J32: Reece | K32: Rory | L32: Ruby | M32: Sam A | N32: Sam L | O32: Will | P32: Caius | Q32: EX5 | S32: Callum | T32: Charlotte | U32: Ellena | V32: George | W32: Harry | X32: Nicola | Y32: Reece | Z32: Rory | AA32: Ruby | AB32: Sam A | AC32: Sam L | AD32: Will | AE32: Caius
C37: Total | R37: Total
C38: CS | R38: CS
B39: GW6 | D39: Callum | E39: Charlotte | F39: Ellena | G39: George | H39: Harry | I39: Nicola | J39: Reece | K39: Rory | L39: Ruby | M39: Sam A | N39: Sam L | O39: Will | P39: Caius | Q39: EX6 | S39: Callum | T39: Charlotte | U39: Ellena | V39: George | W39: Harry | X39: Nicola | Y39: Reece | Z39: Rory | AA39: Ruby | AB39: Sam A | AC39: Sam L | AD39: Will | AE39: Caius
C44: Total | R44: Total
C45: CS | R45: CS
B46: GW7 | D46: Callum | E46: Charlotte | F46: Ellena | G46: George | H46: Harry | I46: Nicola | J46: Reece | K46: Rory | L46: Ruby | M46: Sam A | N46: Sam L | O46: Will | P46: Caius | Q46: EX7 | S46: Callum | T46: Charlotte | U46: Ellena | V46: George | W46: Harry | X46: Nicola | Y46: Reece | Z46: Rory | AA46: Ruby | AB46: Sam A | AC46: Sam L | AD46: Will | AE46: Caius
C51: Total | R51: Total
C52: CS | R52: CS
B53: GW8 | D53: Callum | E53: Charlotte | F53: Ellena | G53: George | H53: Harry | I53: Nicola | J53: Reece | K53: Rory | L53: Ruby | M53: Sam A | N53: Sam L | O53: Will | P53: Caius | Q53: EX8 | S53: Callum | T53: Charlotte | U53: Ellena | V53: George | W53: Harry | X53: Nicola | Y53: Reece | Z53: Rory | AA53: Ruby | AB53: Sam A | AC53: Sam L | AD53: Will | AE53: Caius
C58: Total | R58: Total
C59: CS | R59: CS
B60: GW9 | D60: Callum | E60: Charlotte | F60: Ellena | G60: George | H60: Harry | I60: Nicola | J60: Reece | K60: Rory | L60: Ruby | M60: Sam A | N60: Sam L | O60: Will | P60: Caius | Q60: EX9 | S60: Callum | T60: Charlotte | U60: Ellena | V60: George | W60: Harry | X60: Nicola | Y60: Reece | Z60: Rory | AA60: Ruby | AB60: Sam A | AC60: Sam L | AD60: Will | AE60: Caius
C65: Total | R65: Total
C66: CS | R66: CS
B67: GW10 | D67: Callum | E67: Charlotte | F67: Ellena | G67: George | H67: Harry | I67: Nicola | J67: Reece | K67: Rory | L67: Ruby | M67: Sam A | N67: Sam L | O67: Will | P67: Caius | Q67: EX10 | S67: Callum | T67: Charlotte | U67: Ellena | V67: George | W67: Harry | X67: Nicola | Y67: Reece | Z67: Rory | AA67: Ruby | AB67: Sam A | AC67: Sam L | AD67: Will | AE67: Caius
C72: Total | R72: Total
C73: CS | R73: CS
B74: GW11 | D74: Callum | E74: Charlotte | F74: Ellena | G74: George | H74: Harry | I74: Nicola | J74: Reece | K74: Rory | L74: Ruby | M74: Sam A | N74: Sam L | O74: Will | P74: Caius | Q74: EX11 | S74: Callum | T74: Charlotte | U74: Ellena | V74: George | W74: Harry | X74: Nicola | Y74: Reece | Z74: Rory | AA74: Ruby | AB74: Sam A | AC74: Sam L | AD74: Will | AE74: Caius
C79: Total | R79: Total
C80: CS | R80: CS
B81: GW12 | D81: Callum | E81: Charlotte | F81: Ellena | G81: George | H81: Harry | I81: Nicola | J81: Reece | K81: Rory | L81: Ruby | M81: Sam A | N81: Sam L | O81: Will | P81: Caius | Q81: EX12 | S81: Callum | T81: Charlotte | U81: Ellena | V81: George | W81: Harry | X81: Nicola | Y81: Reece | Z81: Rory | AA81: Ruby | AB81: Sam A | AC81: Sam L | AD81: Will | AE81: Caius
C86: Total | R86: Total
C87: CS | R87: CS
B88: GW13 | D88: Callum | E88: Charlotte | F88: Ellena | G88: George | H88: Harry | I88: Nicola | J88: Reece | K88: Rory | L88: Ruby | M88: Sam A | N88: Sam L | O88: Will | P88: Caius | Q88: EX13 | S88: Callum | T88: Charlotte | U88: Ellena | V88: George | W88: Harry | X88: Nicola | Y88: Reece | Z88: Rory | AA88: Ruby | AB88: Sam A | AC88: Sam L | AD88: Will | AE88: Caius
...

Sheet Leaderboard
A1: Premier League Predictions Table
B4: Position | D4: Player | E4: Points | F4: CS
B5: 1 | D5: {=_xlfn.SORTBY(_xlfn.HSTACK('Extra Results'!M174:M186, 'Extra Results'!N153:N173, 'Extra Results'!L153:L173),'Extra Results'!N153:N173, -1,'Extra Results'!L153:L173, -1)} -> Callum | E5: 0 | F5: 0
B6: 2 | D6: Charlotte | E6: 0 | F6: 0
B7: 3 | D7: Ellena | E7: 0 | F7: 0
B8: 4 | D8: George | E8: 0 | F8: 0
B9: 5 | D9: Harry | E9: 0 | F9: 0
B10: 6 | D10: Nicola | E10: 0 | F10: 0
B11: 7 | D11: Reece | E11: 0 | F11: 0
B12: 8 | D12: Rory | E12: 0 | F12: 0
B13: 9 | D13: Ruby | E13: 0 | F13: 0
B14: 10 | D14: Sam A | E14: 0 | F14: 0
B15: 11 | D15: Sam L | E15: 0 | F15: 0
B16: 12 | D16: Will | E16: 0 | F16: 0
B17: 13 | D17: Caius | E17: 0 | F17: 0
D18: #N/A | E18: 0 | F18: 0
D19: #N/A | E19: 0 | F19: 0
D20: #N/A | E20: 0 | F20: 0
D21: #N/A | E21: 0 | F21: 0
D22: #N/A | E22: 0 | F22: 0
D23: #N/A | E23: 0 | F23: 0
D24: #N/A | E24: 0 | F24: 0
D25: #N/A | E25: 0 | F25: 0

Sheet Extra Results
B2: EXTRA RESULTS
C3: Callum | D3: Charlotte | E3: Ellena | F3: George | G3: Harry | H3: Nicola | I3: Reece | J3: Rory | K3: Ruby | L3: Sam A | M3: Sam L | N3: Will | O3: Caius
C4: {=IF(INDIRECT("Sheet2!S" & 9 + (ROW(C4)-ROW($C$4))*7)=0, "", INDIRECT("Sheet2!S" & 9 + (ROW(C4)-ROW($C$4))*7))} | D4: {=IF(INDIRECT("Sheet2!T" & 9 + (ROW(D4)-ROW($C$4))*7)=0, "", INDIRECT("Sheet2!T" & 9 + (ROW(D4)-ROW($C$4))*7))} | E4: {=IF(INDIRECT("Sheet2!U" & 9 + (ROW(E4)-ROW($C$4))*7)=0, "", INDIRECT("Sheet2!U" & 9 + (ROW(E4)-ROW($C$4))*7))} | F4: {=IF(INDIRECT("Sheet2!V" & 9 + (ROW(F4)-ROW($C$4))*7)=0, "", INDIRECT("Sheet2!V" & 9 + (ROW(F4)-ROW($C$4))*7))} | G4: {=IF(INDIRECT("Sheet2!W" & 9 + (ROW(G4)-ROW($C$4))*7)=0, "", INDIRECT("Sheet2!W" & 9 + (ROW(G4)-ROW($C$4))*7))} | H4: {=IF(INDIRECT("Sheet2!X" & 9 + (ROW(H4)-ROW($C$4))*7)=0, "", INDIRECT("Sheet2!X" & 9 + (ROW(H4)-ROW($C$4))*7))} | I4: {=IF(INDIRECT("Sheet2!Y" & 9 + (ROW(I4)-ROW($C$4))*7)=0, "", INDIRECT("Sheet2!Y" & 9 + (ROW(I4)-ROW($C$4))*7))} | J4: {=IF(INDIRECT("Sheet2!Z" & 9 + (ROW(J4)-ROW($C$4))*7)=0, "", INDIRECT("Sheet2!Z" & 9 + (ROW(J4)-ROW($C$4))*7))} | K4: {=IF(INDIRECT("Sheet2!AA" & 9 + (ROW(K4)-ROW($C$4))*7)=0, "", INDIRECT("Sheet2!AA" & 9 + (ROW(K4)-ROW($C$4))*7))} | L4: {=IF(INDIRECT("Sheet2!AB" & 9 + (ROW(L4)-ROW($C$4))*7)=0, "", INDIRECT("Sheet2!AB" & 9 + (ROW(L4)-ROW($C$4))*7))} | M4: {=IF(INDIRECT("Sheet2!AC" & 9 + (ROW(M4)-ROW($C$4))*7)=0, "", INDIRECT("Sheet2!AC" & 9 + (ROW(M4)-ROW($C$4))*7))} | N4: {=IF(INDIRECT("Sheet2!AD" & 9 + (ROW(N4)-ROW($C$4))*7)=0, "", INDIRECT("Sheet2!AD" & 9 + (ROW(N4)-ROW($C$4))*7))} | O4: {=IF(INDIRECT("Sheet2!AE" & 9 + (ROW(O4)-ROW($C$4))*7)=0, "", INDIRECT("Sheet2!AE" & 9 + (ROW(O4)-ROW($C$4))*7))}
C5: {=IF(INDIRECT("Sheet2!S" & 9 + (ROW(C5)-ROW($C$4))*7)=0, "", INDIRECT("Sheet2!S" & 9 + (ROW(C5)-ROW($C$4))*7))} | D5: {=IF(INDIRECT("Sheet2!T" & 9 + (ROW(D5)-ROW($C$4))*7)=0, "", INDIRECT("Sheet2!T" & 9 + (ROW(D5)-ROW($C$4))*7))} | E5: {=IF(INDIRECT("Sheet2!U" & 9 + (ROW(E5)-ROW($C$4))*7)=0, "", INDIRECT("Sheet2!U" & 9 + (ROW(E5)-ROW($C$4))*7))} | F5: {=IF(INDIRECT("Sheet2!V" & 9 + (ROW(F5)-ROW($C$4))*7)=0, "", INDIRECT("Sheet2!V" & 9 + (ROW(F5)-ROW($C$4))*7))} | G5: {=IF(INDIRECT("Sheet2!W" & 9 + (ROW(G5)-ROW($C$4))*7)=0, "", INDIRECT("Sheet2!W" & 9 + (ROW(G5)-ROW($C$4))*7))} | H5: {=IF(INDIRECT("Sheet2!X" & 9 + (ROW(H5)-ROW($C$4))*7)=0, "", INDIRECT("Sheet2!X" & 9 + (ROW(H5)-ROW($C$4))*7))} | I5: {=IF(INDIRECT("Sheet2!Y" & 9 + (ROW(I5)-ROW($C$4))*7)=0, "", INDIRECT("Sheet2!Y" & 9 + (ROW(I5)-ROW($C$4))*7))} | J5: {=IF(INDIRECT("Sheet2!Z" & 9 + (ROW(J5)-ROW($C$4))*7)=0, "", INDIRECT("Sheet2!Z" & 9 + (ROW(J5)-ROW($C$4))*7))} | K5: {=IF(INDIRECT("Sheet2!AA" & 9 + (ROW(K5)-ROW($C$4))*7)=0, "", INDIRECT("Sheet2!AA" & 9 + (ROW(K5)-ROW($C$4))*7))} | L5: {=IF(INDIRECT("Sheet2!AB" & 9 + (ROW(L5)-ROW($C$4))*7)=0, "", INDIRECT("Sheet2!AB" & 9 + (ROW(L5)-ROW($C$4))*7))} | M5: {=IF(INDIRECT("Sheet2!AC" & 9 + (ROW(M5)-ROW($C$4))*7)=0, "", INDIRECT("Sheet2!AC" & 9 + (ROW(M5)-ROW($C$4))*7))} | N5: {=IF(INDIRECT("Sheet2!AD" & 9 + (ROW(N5)-ROW($C$4))*7)=0, "", INDIRECT("Sheet2!AD" & 9 + (ROW(N5)-ROW($C$4))*7))} | O5: {=IF(INDIRECT("Sheet2!AE" & 9 + (ROW(O5)-ROW($C$4))*7)=0, "", INDIRECT("Sheet2!AE" & 9 + (ROW(O5)-ROW($C$4))*7))}
C6: {=IF(INDIRECT("Sheet2!S" & 9 + (ROW(C6)-ROW($C$4))*7)=0, "", INDIRECT("Sheet2!S" & 9 + (ROW(C6)-ROW($C$4))*7))} | D6: {=IF(INDIRECT("Sheet2!T" & 9 + (ROW(D6)-ROW($C$4))*7)=0, "", INDIRECT("Sheet2!T" & 9 + (ROW(D6)-ROW($C$4))*7))} | E6: {=IF(INDIRECT("Sheet2!U" & 9 + (ROW(E6)-ROW($C$4))*7)=0, "", INDIRECT("Sheet2!U" & 9 + (ROW(E6)-ROW($C$4))*7))} | F6: {=IF(INDIRECT("Sheet2!V" & 9 + (ROW(F6)-ROW($C$4))*7)=0, "", INDIRECT("Sheet2!V" & 9 + (ROW(F6)-ROW($C$4))*7))} | G6: {=IF(INDIRECT("Sheet2!W" & 9 + (ROW(G6)-ROW($C$4))*7)=0, "", INDIRECT("Sheet2!W" & 9 + (ROW(G6)-ROW($C$4))*7))} | H6: {=IF(INDIRECT("Sheet2!X" & 9 + (ROW(H6)-ROW($C$4))*7)=0, "", INDIRECT("Sheet2!X" & 9 + (ROW(H6)-ROW($C$4))*7))} | I6: {=IF(INDIRECT("Sheet2!Y" & 9 + (ROW(I6)-ROW($C$4))*7)=0, "", INDIRECT("Sheet2!Y" & 9 + (ROW(I6)-ROW($C$4))*7))} | J6: {=IF(INDIRECT("Sheet2!Z" & 9 + (ROW(J6)-ROW($C$4))*7)=0, "", INDIRECT("Sheet2!Z" & 9 + (ROW(J6)-ROW($C$4))*7))} | K6: {=IF(INDIRECT("Sheet2!AA" & 9 + (ROW(K6)-ROW($C$4))*7)=0, "", INDIRECT("Sheet2!AA" & 9 + (ROW(K6)-ROW($C$4))*7))} | L6: {=IF(INDIRECT("Sheet2!AB" & 9 + (ROW(L6)-ROW($C$4))*7)=0, "", INDIRECT("Sheet2!AB" & 9 + (ROW(L6)-ROW($C$4))*7))} | M6: {=IF(INDIRECT("Sheet2!AC" & 9 + (ROW(M6)-ROW($C$4))*7)=0, "", INDIRECT("Sheet2!AC" & 9 + (ROW(M6)-ROW($C$4))*7))} | N6: {=IF(INDIRECT("Sheet2!AD" & 9 + (ROW(N6)-ROW($C$4))*7)=0, "", INDIRECT("Sheet2!AD" & 9 + (ROW(N6)-ROW($C$4))*7))} | O6: {=IF(INDIRECT("Sheet2!AE" & 9 + (ROW(O6)-ROW($C$4))*7)=0, "", INDIRECT("Sheet2!AE" & 9 + (ROW(O6)-ROW($C$4))*7))}
C7: {=IF(INDIRECT("Sheet2!S" & 9 + (ROW(C7)-ROW($C$4))*7)=0, "", INDIRECT("Sheet2!S" & 9 + (ROW(C7)-ROW($C$4))*7))} | D7: {=IF(INDIRECT("Sheet2!T" & 9 + (ROW(D7)-ROW($C$4))*7)=0, "", INDIRECT("Sheet2!T" & 9 + (ROW(D7)-ROW($C$4))*7))} | E7: {=IF(INDIRECT("Sheet2!U" & 9 + (ROW(E7)-ROW($C$4))*7)=0, "", INDIRECT("Sheet2!U" & 9 + (ROW(E7)-ROW($C$4))*7))} | F7: {=IF(INDIRECT("Sheet2!V" & 9 + (ROW(F7)-ROW($C$4))*7)=0, "", INDIRECT("Sheet2!V" & 9 + (ROW(F7)-ROW($C$4))*7))} | G7: {=IF(INDIRECT("Sheet2!W" & 9 + (ROW(G7)-ROW($C$4))*7)=0, "", INDIRECT("Sheet2!W" & 9 + (ROW(G7)-ROW($C$4))*7))} | H7: {=IF(INDIRECT("Sheet2!X" & 9 + (ROW(H7)-ROW($C$4))*7)=0, "", INDIRECT("Sheet2!X" & 9 + (ROW(H7)-ROW($C$4))*7))} | I7: {=IF(INDIRECT("Sheet2!Y" & 9 + (ROW(I7)-ROW($C$4))*7)=0, "", INDIRECT("Sheet2!Y" & 9 + (ROW(I7)-ROW($C$4))*7))} | J7: {=IF(INDIRECT("Sheet2!Z" & 9 + (ROW(J7)-ROW($C$4))*7)=0, "", INDIRECT("Sheet2!Z" & 9 + (ROW(J7)-ROW($C$4))*7))} | K7: {=IF(INDIRECT("Sheet2!AA" & 9 + (ROW(K7)-ROW($C$4))*7)=0, "", INDIRECT("Sheet2!AA" & 9 + (ROW(K7)-ROW($C$4))*7))} | L7: {=IF(INDIRECT("Sheet2!AB" & 9 + (ROW(L7)-ROW($C$4))*7)=0, "", INDIRECT("Sheet2!AB" & 9 + (ROW(L7)-ROW($C$4))*7))} | M7: {=IF(INDIRECT("Sheet2!AC" & 9 + (ROW(M7)-ROW($C$4))*7)=0, "", INDIRECT("Sheet2!AC" & 9 + (ROW(M7)-ROW($C$4))*7))} | N7: {=IF(INDIRECT("Sheet2!AD" & 9 + (ROW(N7)-ROW($C$4))*7)=0, "", INDIRECT("Sheet2!AD" & 9 + (ROW(N7)-ROW($C$4))*7))} | O7: {=IF(INDIRECT("Sheet2!AE" & 9 + (ROW(O7)-ROW($C$4))*7)=0, "", INDIRECT("Sheet2!AE" & 9 + (ROW(O7)-ROW($C$4))*7))}
C8: {=IF(INDIRECT("Sheet2!S" & 9 + (ROW(C8)-ROW($C$4))*7)=0, "", INDIRECT("Sheet2!S" & 9 + (ROW(C8)-ROW($C$4))*7))} | D8: {=IF(INDIRECT("Sheet2!T" & 9 + (ROW(D8)-ROW($C$4))*7)=0, "", INDIRECT("Sheet2!T" & 9 + (ROW(D8)-ROW($C$4))*7))} | E8: {=IF(INDIRECT("Sheet2!U" & 9 + (ROW(E8)-ROW($C$4))*7)=0, "", INDIRECT("Sheet2!U" & 9 + (ROW(E8)-ROW($C$4))*7))} | F8: {=IF(INDIRECT("Sheet2!V" & 9 + (ROW(F8)-ROW($C$4))*7)=0, "", INDIRECT("Sheet2!V" & 9 + (ROW(F8)-ROW($C$4))*7))} | G8: {=IF(INDIRECT("Sheet2!W" & 9 + (ROW(G8)-ROW($C$4))*7)=0, "", INDIRECT("Sheet2!W" & 9 + (ROW(G8)-ROW($C$4))*7))} | H8: {=IF(INDIRECT("Sheet2!X" & 9 + (ROW(H8)-ROW($C$4))*7)=0, "", INDIRECT("Sheet2!X" & 9 + (ROW(H8)-ROW($C$4))*7))} | I8: {=IF(INDIRECT("Sheet2!Y" & 9 + (ROW(I8)-ROW($C$4))*7)=0, "", INDIRECT("Sheet2!Y" & 9 + (ROW(I8)-ROW($C$4))*7))} | J8: {=IF(INDIRECT("Sheet2!Z" & 9 + (ROW(J8)-ROW($C$4))*7)=0, "", INDIRECT("Sheet2!Z" & 9 + (ROW(J8)-ROW($C$4))*7))} | K8: {=IF(INDIRECT("Sheet2!AA" & 9 + (ROW(K8)-ROW($C$4))*7)=0, "", INDIRECT("Sheet2!AA" & 9 + (ROW(K8)-ROW($C$4))*7))} | L8: {=IF(INDIRECT("Sheet2!AB" & 9 + (ROW(L8)-ROW($C$4))*7)=0, "", INDIRECT("Sheet2!AB" & 9 + (ROW(L8)-ROW($C$4))*7))} | M8: {=IF(INDIRECT("Sheet2!AC" & 9 + (ROW(M8)-ROW($C$4))*7)=0, "", INDIRECT("Sheet2!AC" & 9 + (ROW(M8)-ROW($C$4))*7))} | N8: {=IF(INDIRECT("Sheet2!AD" & 9 + (ROW(N8)-ROW($C$4))*7)=0, "", INDIRECT("Sheet2!AD" & 9 + (ROW(N8)-ROW($C$4))*7))} | O8: {=IF(INDIRECT("Sheet2!AE" & 9 + (ROW(O8)-ROW($C$4))*7)=0, "", INDIRECT("Sheet2!AE" & 9 + (ROW(O8)-ROW($C$4))*7))}
C9: {=IF(INDIRECT("Sheet2!S" & 9 + (ROW(C9)-ROW($C$4))*7)=0, "", INDIRECT("Sheet2!S" & 9 + (ROW(C9)-ROW($C$4))*7))} | D9: {=IF(INDIRECT("Sheet2!T" & 9 + (ROW(D9)-ROW($C$4))*7)=0, "", INDIRECT("Sheet2!T" & 9 + (ROW(D9)-ROW($C$4))*7))} | E9: {=IF(INDIRECT("Sheet2!U" & 9 + (ROW(E9)-ROW($C$4))*7)=0, "", INDIRECT("Sheet2!U" & 9 + (ROW(E9)-ROW($C$4))*7))} | F9: {=IF(INDIRECT("Sheet2!V" & 9 + (ROW(F9)-ROW($C$4))*7)=0, "", INDIRECT("Sheet2!V" & 9 + (ROW(F9)-ROW($C$4))*7))} | G9: {=IF(INDIRECT("Sheet2!W" & 9 + (ROW(G9)-ROW($C$4))*7)=0, "", INDIRECT("Sheet2!W" & 9 + (ROW(G9)-ROW($C$4))*7))} | H9: {=IF(INDIRECT("Sheet2!X" & 9 + (ROW(H9)-ROW($C$4))*7)=0, "", INDIRECT("Sheet2!X" & 9 + (ROW(H9)-ROW($C$4))*7))} | I9: {=IF(INDIRECT("Sheet2!Y" & 9 + (ROW(I9)-ROW($C$4))*7)=0, "", INDIRECT("Sheet2!Y" & 9 + (ROW(I9)-ROW($C$4))*7))} | J9: {=IF(INDIRECT("Sheet2!Z" & 9 + (ROW(J9)-ROW($C$4))*7)=0, "", INDIRECT("Sheet2!Z" & 9 + (ROW(J9)-ROW($C$4))*7))} | K9: {=IF(INDIRECT("Sheet2!AA" & 9 + (ROW(K9)-ROW($C$4))*7)=0, "", INDIRECT("Sheet2!AA" & 9 + (ROW(K9)-ROW($C$4))*7))} | L9: {=IF(INDIRECT("Sheet2!AB" & 9 + (ROW(L9)-ROW($C$4))*7)=0, "", INDIRECT("Sheet2!AB" & 9 + (ROW(L9)-ROW($C$4))*7))} | M9: {=IF(INDIRECT("Sheet2!AC" & 9 + (ROW(M9)-ROW($C$4))*7)=0, "", INDIRECT("Sheet2!AC" & 9 + (ROW(M9)-ROW($C$4))*7))} | N9: {=IF(INDIRECT("Sheet2!AD" & 9 + (ROW(N9)-ROW($C$4))*7)=0, "", INDIRECT("Sheet2!AD" & 9 + (ROW(N9)-ROW($C$4))*7))} | O9: {=IF(INDIRECT("Sheet2!AE" & 9 + (ROW(O9)-ROW($C$4))*7)=0, "", INDIRECT("Sheet2!AE" & 9 + (ROW(O9)-ROW($C$4))*7))}
C10: {=IF(INDIRECT("Sheet2!S" & 9 + (ROW(C10)-ROW($C$4))*7)=0, "", INDIRECT("Sheet2!S" & 9 + (ROW(C10)-ROW($C$4))*7))} | D10: {=IF(INDIRECT("Sheet2!T" & 9 + (ROW(D10)-ROW($C$4))*7)=0, "", INDIRECT("Sheet2!T" & 9 + (ROW(D10)-ROW($C$4))*7))} | E10: {=IF(INDIRECT("Sheet2!U" & 9 + (ROW(E10)-ROW($C$4))*7)=0, "", INDIRECT("Sheet2!U" & 9 + (ROW(E10)-ROW($C$4))*7))} | F10: {=IF(INDIRECT("Sheet2!V" & 9 + (ROW(F10)-ROW($C$4))*7)=0, "", INDIRECT("Sheet2!V" & 9 + (ROW(F10)-ROW($C$4))*7))} | G10: {=IF(INDIRECT("Sheet2!W" & 9 + (ROW(G10)-ROW($C$4))*7)=0, "", INDIRECT("Sheet2!W" & 9 + (ROW(G10)-ROW($C$4))*7))} | H10: {=IF(INDIRECT("Sheet2!X" & 9 + (ROW(H10)-ROW($C$4))*7)=0, "", INDIRECT("Sheet2!X" & 9 + (ROW(H10)-ROW($C$4))*7))} | I10: {=IF(INDIRECT("Sheet2!Y" & 9 + (ROW(I10)-ROW($C$4))*7)=0, "", INDIRECT("Sheet2!Y" & 9 + (ROW(I10)-ROW($C$4))*7))} | J10: {=IF(INDIRECT("Sheet2!Z" & 9 + (ROW(J10)-ROW($C$4))*7)=0, "", INDIRECT("Sheet2!Z" & 9 + (ROW(J10)-ROW($C$4))*7))} | K10: {=IF(INDIRECT("Sheet2!AA" & 9 + (ROW(K10)-ROW($C$4))*7)=0, "", INDIRECT("Sheet2!AA" & 9 + (ROW(K10)-ROW($C$4))*7))} | L10: {=IF(INDIRECT("Sheet2!AB" & 9 + (ROW(L10)-ROW($C$4))*7)=0, "", INDIRECT("Sheet2!AB" & 9 + (ROW(L10)-ROW($C$4))*7))} | M10: {=IF(INDIRECT("Sheet2!AC" & 9 + (ROW(M10)-ROW($C$4))*7)=0, "", INDIRECT("Sheet2!AC" & 9 + (ROW(M10)-ROW($C$4))*7))} | N10: {=IF(INDIRECT("Sheet2!AD" & 9 + (ROW(N10)-ROW($C$4))*7)=0, "", INDIRECT("Sheet2!AD" & 9 + (ROW(N10)-ROW($C$4))*7))} | O10: {=IF(INDIRECT("Sheet2!AE" & 9 + (ROW(O10)-ROW($C$4))*7)=0, "", INDIRECT("Sheet2!AE" & 9 + (ROW(O10)-ROW($C$4))*7))}
C11: {=IF(INDIRECT("Sheet2!S" & 9 + (ROW(C11)-ROW($C$4))*7)=0, "", INDIRECT("Sheet2!S" & 9 + (ROW(C11)-ROW($C$4))*7))} | D11: {=IF(INDIRECT("Sheet2!T" & 9 + (ROW(D11)-ROW($C$4))*7)=0, "", INDIRECT("Sheet2!T" & 9 + (ROW(D11)-ROW($C$4))*7))} | E11: {=IF(INDIRECT("Sheet2!U" & 9 + (ROW(E11)-ROW($C$4))*7)=0, "", INDIRECT("Sheet2!U" & 9 + (ROW(E11)-ROW($C$4))*7))} | F11: {=IF(INDIRECT("Sheet2!V" & 9 + (ROW(F11)-ROW($C$4))*7)=0, "", INDIRECT("Sheet2!V" & 9 + (ROW(F11)-ROW($C$4))*7))} | G11: {=IF(INDIRECT("Sheet2!W" & 9 + (ROW(G11)-ROW($C$4))*7)=0, "", INDIRECT("Sheet2!W" & 9 + (ROW(G11)-ROW($C$4))*7))} | H11: {=IF(INDIRECT("Sheet2!X" & 9 + (ROW(H11)-ROW($C$4))*7)=0, "", INDIRECT("Sheet2!X" & 9 + (ROW(H11)-ROW($C$4))*7))} | I11: {=IF(INDIRECT("Sheet2!Y" & 9 + (ROW(I11)-ROW($C$4))*7)=0, "", INDIRECT("Sheet2!Y" & 9 + (ROW(I11)-ROW($C$4))*7))} | J11: {=IF(INDIRECT("Sheet2!Z" & 9 + (ROW(J11)-ROW($C$4))*7)=0, "", INDIRECT("Sheet2!Z" & 9 + (ROW(J11)-ROW($C$4))*7))} | K11: {=IF(INDIRECT("Sheet2!AA" & 9 + (ROW(K11)-ROW($C$4))*7)=0, "", INDIRECT("Sheet2!AA" & 9 + (ROW(K11)-ROW($C$4))*7))} | L11: {=IF(INDIRECT("Sheet2!AB" & 9 + (ROW(L11)-ROW($C$4))*7)=0, "", INDIRECT("Sheet2!AB" & 9 + (ROW(L11)-ROW($C$4))*7))} | M11: {=IF(INDIRECT("Sheet2!AC" & 9 + (ROW(M11)-ROW($C$4))*7)=0, "", INDIRECT("Sheet2!AC" & 9 + (ROW(M11)-ROW($C$4))*7))} | N11: {=IF(INDIRECT("Sheet2!AD" & 9 + (ROW(N11)-ROW($C$4))*7)=0, "", INDIRECT("Sheet2!AD" & 9 + (ROW(N11)-ROW($C$4))*7))} | O11: {=IF(INDIRECT("Sheet2!AE" & 9 + (ROW(O11)-ROW($C$4))*7)=0, "", INDIRECT("Sheet2!AE" & 9 + (ROW(O11)-ROW($C$4))*7))}
C12: {=IF(INDIRECT("Sheet2!S" & 9 + (ROW(C12)-ROW($C$4))*7)=0, "", INDIRECT("Sheet2!S" & 9 + (ROW(C12)-ROW($C$4))*7))} | D12: {=IF(INDIRECT("Sheet2!T" & 9 + (ROW(D12)-ROW($C$4))*7)=0, "", INDIRECT("Sheet2!T" & 9 + (ROW(D12)-ROW($C$4))*7))} | E12: {=IF(INDIRECT("Sheet2!U" & 9 + (ROW(E12)-ROW($C$4))*7)=0, "", INDIRECT("Sheet2!U" & 9 + (ROW(E12)-ROW($C$4))*7))} | F12: {=IF(INDIRECT("Sheet2!V" & 9 + (ROW(F12)-ROW($C$4))*7)=0, "", INDIRECT("Sheet2!V" & 9 + (ROW(F12)-ROW($C$4))*7))} | G12: {=IF(INDIRECT("Sheet2!W" & 9 + (ROW(G12)-ROW($C$4))*7)=0, "", INDIRECT("Sheet2!W" & 9 + (ROW(G12)-ROW($C$4))*7))} | H12: {=IF(INDIRECT("Sheet2!X" & 9 + (ROW(H12)-ROW($C$4))*7)=0, "", INDIRECT("Sheet2!X" & 9 + (ROW(H12)-ROW($C$4))*7))} | I12: {=IF(INDIRECT("Sheet2!Y" & 9 + (ROW(I12)-ROW($C$4))*7)=0, "", INDIRECT("Sheet2!Y" & 9 + (ROW(I12)-ROW($C$4))*7))} | J12: {=IF(INDIRECT("Sheet2!Z" & 9 + (ROW(J12)-ROW($C$4))*7)=0, "", INDIRECT("Sheet2!Z" & 9 + (ROW(J12)-ROW($C$4))*7))} | K12: {=IF(INDIRECT("Sheet2!AA" & 9 + (ROW(K12)-ROW($C$4))*7)=0, "", INDIRECT("Sheet2!AA" & 9 + (ROW(K12)-ROW($C$4))*7))} | L12: {=IF(INDIRECT("Sheet2!AB" & 9 + (ROW(L12)-ROW($C$4))*7)=0, "", INDIRECT("Sheet2!AB" & 9 + (ROW(L12)-ROW($C$4))*7))} | M12: {=IF(INDIRECT("Sheet2!AC" & 9 + (ROW(M12)-ROW($C$4))*7)=0, "", INDIRECT("Sheet2!AC" & 9 + (ROW(M12)-ROW($C$4))*7))} | N12: {=IF(INDIRECT("Sheet2!AD" & 9 + (ROW(N12)-ROW($C$4))*7)=0, "", INDIRECT("Sheet2!AD" & 9 + (ROW(N12)-ROW($C$4))*7))} | O12: {=IF(INDIRECT("Sheet2!AE" & 9 + (ROW(O12)-ROW($C$4))*7)=0, "", INDIRECT("Sheet2!AE" & 9 + (ROW(O12)-ROW($C$4))*7))}
C13: {=IF(INDIRECT("Sheet2!S" & 9 + (ROW(C13)-ROW($C$4))*7)=0, "", INDIRECT("Sheet2!S" & 9 + (ROW(C13)-ROW($C$4))*7))} | D13: {=IF(INDIRECT("Sheet2!T" & 9 + (ROW(D13)-ROW($C$4))*7)=0, "", INDIRECT("Sheet2!T" & 9 + (ROW(D13)-ROW($C$4))*7))} | E13: {=IF(INDIRECT("Sheet2!U" & 9 + (ROW(E13)-ROW($C$4))*7)=0, "", INDIRECT("Sheet2!U" & 9 + (ROW(E13)-ROW($C$4))*7))} | F13: {=IF(INDIRECT("Sheet2!V" & 9 + (ROW(F13)-ROW($C$4))*7)=0, "", INDIRECT("Sheet2!V" & 9 + (ROW(F13)-ROW($C$4))*7))} | G13: {=IF(INDIRECT("Sheet2!W" & 9 + (ROW(G13)-ROW($C$4))*7)=0, "", INDIRECT("Sheet2!W" & 9 + (ROW(G13)-ROW($C$4))*7))} | H13: {=IF(INDIRECT("Sheet2!X" & 9 + (ROW(H13)-ROW($C$4))*7)=0, "", INDIRECT("Sheet2!X" & 9 + (ROW(H13)-ROW($C$4))*7))} | I13: {=IF(INDIRECT("Sheet2!Y" & 9 + (ROW(I13)-ROW($C$4))*7)=0, "", INDIRECT("Sheet2!Y" & 9 + (ROW(I13)-ROW($C$4))*7))} | J13: {=IF(INDIRECT("Sheet2!Z" & 9 + (ROW(J13)-ROW($C$4))*7)=0, "", INDIRECT("Sheet2!Z" & 9 + (ROW(J13)-ROW($C$4))*7))} | K13: {=IF(INDIRECT("Sheet2!AA" & 9 + (ROW(K13)-ROW($C$4))*7)=0, "", INDIRECT("Sheet2!AA" & 9 + (ROW(K13)-ROW($C$4))*7))} | L13: {=IF(INDIRECT("Sheet2!AB" & 9 + (ROW(L13)-ROW($C$4))*7)=0, "", INDIRECT("Sheet2!AB" & 9 + (ROW(L13)-ROW($C$4))*7))} | M13: {=IF(INDIRECT("Sheet2!AC" & 9 + (ROW(M13)-ROW($C$4))*7)=0, "", INDIRECT("Sheet2!AC" & 9 + (ROW(M13)-ROW($C$4))*7))} | N13: {=IF(INDIRECT("Sheet2!AD" & 9 + (ROW(N13)-ROW($C$4))*7)=0, "", INDIRECT("Sheet2!AD" & 9 + (ROW(N13)-ROW($C$4))*7))} | O13: {=IF(INDIRECT("Sheet2!AE" & 9 + (ROW(O13)-ROW($C$4))*7)=0, "", INDIRECT("Sheet2!AE" & 9 + (ROW(O13)-ROW($C$4))*7))}
C14: {=IF(INDIRECT("Sheet2!S" & 9 + (ROW(C14)-ROW($C$4))*7)=0, "", INDIRECT("Sheet2!S" & 9 + (ROW(C14)-ROW($C$4))*7))} | D14: {=IF(INDIRECT("Sheet2!T" & 9 + (ROW(D14)-ROW($C$4))*7)=0, "", INDIRECT("Sheet2!T" & 9 + (ROW(D14)-ROW($C$4))*7))} | E14: {=IF(INDIRECT("Sheet2!U" & 9 + (ROW(E14)-ROW($C$4))*7)=0, "", INDIRECT("Sheet2!U" & 9 + (ROW(E14)-ROW($C$4))*7))} | F14: {=IF(INDIRECT("Sheet2!V" & 9 + (ROW(F14)-ROW($C$4))*7)=0, "", INDIRECT("Sheet2!V" & 9 + (ROW(F14)-ROW($C$4))*7))} | G14: {=IF(INDIRECT("Sheet2!W" & 9 + (ROW(G14)-ROW($C$4))*7)=0, "", INDIRECT("Sheet2!W" & 9 + (ROW(G14)-ROW($C$4))*7))} | H14: {=IF(INDIRECT("Sheet2!X" & 9 + (ROW(H14)-ROW($C$4))*7)=0, "", INDIRECT("Sheet2!X" & 9 + (ROW(H14)-ROW($C$4))*7))} | I14: {=IF(INDIRECT("Sheet2!Y" & 9 + (ROW(I14)-ROW($C$4))*7)=0, "", INDIRECT("Sheet2!Y" & 9 + (ROW(I14)-ROW($C$4))*7))} | J14: {=IF(INDIRECT("Sheet2!Z" & 9 + (ROW(J14)-ROW($C$4))*7)=0, "", INDIRECT("Sheet2!Z" & 9 + (ROW(J14)-ROW($C$4))*7))} | K14: {=IF(INDIRECT("Sheet2!AA" & 9 + (ROW(K14)-ROW($C$4))*7)=0, "", INDIRECT("Sheet2!AA" & 9 + (ROW(K14)-ROW($C$4))*7))} | L14: {=IF(INDIRECT("Sheet2!AB" & 9 + (ROW(L14)-ROW($C$4))*7)=0, "", INDIRECT("Sheet2!AB" & 9 + (ROW(L14)-ROW($C$4))*7))} | M14: {=IF(INDIRECT("Sheet2!AC" & 9 + (ROW(M14)-ROW($C$4))*7)=0, "", INDIRECT("Sheet2!AC" & 9 + (ROW(M14)-ROW($C$4))*7))} | N14: {=IF(INDIRECT("Sheet2!AD" & 9 + (ROW(N14)-ROW($C$4))*7)=0, "", INDIRECT("Sheet2!AD" & 9 + (ROW(N14)-ROW($C$4))*7))} | O14: {=IF(INDIRECT("Sheet2!AE" & 9 + (ROW(O14)-ROW($C$4))*7)=0, "", INDIRECT("Sheet2!AE" & 9 + (ROW(O14)-ROW($C$4))*7))}
C15: {=IF(INDIRECT("Sheet2!S" & 9 + (ROW(C15)-ROW($C$4))*7)=0, "", INDIRECT("Sheet2!S" & 9 + (ROW(C15)-ROW($C$4))*7))} | D15: {=IF(INDIRECT("Sheet2!T" & 9 + (ROW(D15)-ROW($C$4))*7)=0, "", INDIRECT("Sheet2!T" & 9 + (ROW(D15)-ROW($C$4))*7))} | E15: {=IF(INDIRECT("Sheet2!U" & 9 + (ROW(E15)-ROW($C$4))*7)=0, "", INDIRECT("Sheet2!U" & 9 + (ROW(E15)-ROW($C$4))*7))} | F15: {=IF(INDIRECT("Sheet2!V" & 9 + (ROW(F15)-ROW($C$4))*7)=0, "", INDIRECT("Sheet2!V" & 9 + (ROW(F15)-ROW($C$4))*7))} | G15: {=IF(INDIRECT("Sheet2!W" & 9 + (ROW(G15)-ROW($C$4))*7)=0, "", INDIRECT("Sheet2!W" & 9 + (ROW(G15)-ROW($C$4))*7))} | H15: {=IF(INDIRECT("Sheet2!X" & 9 + (ROW(H15)-ROW($C$4))*7)=0, "", INDIRECT("Sheet2!X" & 9 + (ROW(H15)-ROW($C$4))*7))} | I15: {=IF(INDIRECT("Sheet2!Y" & 9 + (ROW(I15)-ROW($C$4))*7)=0, "", INDIRECT("Sheet2!Y" & 9 + (ROW(I15)-ROW($C$4))*7))} | J15: {=IF(INDIRECT("Sheet2!Z" & 9 + (ROW(J15)-ROW($C$4))*7)=0, "", INDIRECT("Sheet2!Z" & 9 + (ROW(J15)-ROW($C$4))*7))} | K15: {=IF(INDIRECT("Sheet2!AA" & 9 + (ROW(K15)-ROW($C$4))*7)=0, "", INDIRECT("Sheet2!AA" & 9 + (ROW(K15)-ROW($C$4))*7))} | L15: {=IF(INDIRECT("Sheet2!AB" & 9 + (ROW(L15)-ROW($C$4))*7)=0, "", INDIRECT("Sheet2!AB" & 9 + (ROW(L15)-ROW($C$4))*7))} | M15: {=IF(INDIRECT("Sheet2!AC" & 9 + (ROW(M15)-ROW($C$4))*7)=0, "", INDIRECT("Sheet2!AC" & 9 + (ROW(M15)-ROW($C$4))*7))} | N15: {=IF(INDIRECT("Sheet2!AD" & 9 + (ROW(N15)-ROW($C$4))*7)=0, "", INDIRECT("Sheet2!AD" & 9 + (ROW(N15)-ROW($C$4))*7))} | O15: {=IF(INDIRECT("Sheet2!AE" & 9 + (ROW(O15)-ROW($C$4))*7)=0, "", INDIRECT("Sheet2!AE" & 9 + (ROW(O15)-ROW($C$4))*7))}
... C41: {=IF(INDIRECT("Sheet2!S" & 9 + (ROW(C41)-ROW($C$4))*7)=0, "", INDIRECT("Sheet2!S" & 9 + (ROW(C41)-ROW($C$4))*7))} | D41: {=IF(INDIRECT("Sheet2!T" & 9 + (ROW(D41)-ROW($C$4))*7)=0, "", INDIRECT("Sheet2!T" & 9 + (ROW(D41)-ROW($C$4))*7))} | E41: {=IF(INDIRECT("Sheet2!U" & 9 + (ROW(E41)-ROW($C$4))*7)=0, "", INDIRECT("Sheet2!U" & 9 + (ROW(E41)-ROW($C$4))*7))} | F41: {=IF(INDIRECT("Sheet2!V" & 9 + (ROW(F41)-ROW($C$4))*7)=0, "", INDIRECT("Sheet2!V" & 9 + (ROW(F41)-ROW($C$4))*7))} | G41: {=IF(INDIRECT("Sheet2!W" & 9 + (ROW(G41)-ROW($C$4))*7)=0, "", INDIRECT("Sheet2!W" & 9 + (ROW(G41)-ROW($C$4))*7))} | H41: {=IF(INDIRECT("Sheet2!X" & 9 + (ROW(H41)-ROW($C$4))*7)=0, "", INDIRECT("Sheet2!X" & 9 + (ROW(H41)-ROW($C$4))*7))} | I41: {=IF(INDIRECT("Sheet2!Y" & 9 + (ROW(I41)-ROW($C$4))*7)=0, "", INDIRECT("Sheet2!Y" & 9 + (ROW(I41)-ROW($C$4))*7))} | J41: {=IF(INDIRECT("Sheet2!Z" & 9 + (ROW(J41)-ROW($C$4))*7)=0, "", INDIRECT("Sheet2!Z" & 9 + (ROW(J41)-ROW($C$4))*7))} | K41: {=IF(INDIRECT("Sheet2!AA" & 9 + (ROW(K41)-ROW($C$4))*7)=0, "", INDIRECT("Sheet2!AA" & 9 + (ROW(K41)-ROW($C$4))*7))} | L41: {=IF(INDIRECT("Sheet2!AB" & 9 + (ROW(L41)-ROW($C$4))*7)=0, "", INDIRECT("Sheet2!AB" & 9 + (ROW(L41)-ROW($C$4))*7))} | M41: {=IF(INDIRECT("Sheet2!AC" & 9 + (ROW(M41)-ROW($C$4))*7)=0, "", INDIRECT("Sheet2!AC" & 9 + (ROW(M41)-ROW($C$4))*7))} | N41: {=IF(INDIRECT("Sheet2!AD" & 9 + (ROW(N41)-ROW($C$4))*7)=0, "", INDIRECT("Sheet2!AD" & 9 + (ROW(N41)-ROW($C$4))*7))} | O41: {=IF(INDIRECT("Sheet2!AE" & 9 + (ROW(O41)-ROW($C$4))*7)=0, "", INDIRECT("Sheet2!AE" & 9 + (ROW(O41)-ROW($C$4))*7))}
B42: Total | C42: =SUM(C4:C41) -> 0 | D42: =SUM(D4:D41) -> 0 | E42: =SUM(E4:E41) -> 0 | F42: =SUM(F4:F41) -> 0 | G42: =SUM(G4:G41) -> 0 | H42: =SUM(H4:H41) -> 0 | I42: =SUM(I4:I41) -> 0 | J42: =SUM(J4:J41) -> 0 | ... O42: =SUM(O4:O41) -> 0
B49: PL CS
C50: Callum | D50: Charlotte | E50: Ellena | F50: George | G50: Harry | H50: Nicola | I50: Reece | J50: Rory | K50: Ruby | L50: Sam A | M50: Sam L | N50: Will | O50: Caius
C51: {=INDIRECT("Sheet2!D" & 10 + (ROW(C4)-ROW($C$4))*7)} -> 0 | D51: {=INDIRECT("Sheet2!E" & 10 + (ROW(D4)-ROW($C$4))*7)} -> 0 | E51: {=INDIRECT("Sheet2!F" & 10 + (ROW(E4)-ROW($C$4))*7)} -> 0 | F51: {=INDIRECT("Sheet2!G" & 10 + (ROW(F4)-ROW($C$4))*7)} -> 0 | G51: {=INDIRECT("Sheet2!H" & 10 + (ROW(G4)-ROW($C$4))*7)} -> 0 | H51: {=INDIRECT("Sheet2!I" & 10 + (ROW(H4)-ROW($C$4))*7)} -> 0 | I51: {=INDIRECT("Sheet2!J" & 10 + (ROW(I4)-ROW($C$4))*7)} -> 0 | J51: {=INDIRECT("Sheet2!K" & 10 + (ROW(J4)-ROW($C$4))*7)} -> 0 | K51: {=INDIRECT("Sheet2!L" & 10 + (ROW(K4)-ROW($C$4))*7)} -> 0 | L51: {=INDIRECT("Sheet2!M" & 10 + (ROW(L4)-ROW($C$4))*7)} -> 0 | M51: {=INDIRECT("Sheet2!N" & 10 + (ROW(M4)-ROW($C$4))*7)} -> 0 | N51: {=INDIRECT("Sheet2!o" & 10 + (ROW(N4)-ROW($C$4))*7)} -> 0 | O51: {=INDIRECT("Sheet2!p" & 10 + (ROW(O4)-ROW($C$4))*7)} -> 0
C52: {=INDIRECT("Sheet2!D" & 10 + (ROW(C5)-ROW($C$4))*7)} -> 0 | D52: {=INDIRECT("Sheet2!E" & 10 + (ROW(D5)-ROW($C$4))*7)} -> 0 | E52: {=INDIRECT("Sheet2!F" & 10 + (ROW(E5)-ROW($C$4))*7)} -> 0 | F52: {=INDIRECT("Sheet2!G" & 10 + (ROW(F5)-ROW($C$4))*7)} -> 0 | G52: {=INDIRECT("Sheet2!H" & 10 + (ROW(G5)-ROW($C$4))*7)} -> 0 | H52: {=INDIRECT("Sheet2!I" & 10 + (ROW(H5)-ROW($C$4))*7)} -> 0 | I52: {=INDIRECT("Sheet2!J" & 10 + (ROW(I5)-ROW($C$4))*7)} -> 0 | J52: {=INDIRECT("Sheet2!K" & 10 + (ROW(J5)-ROW($C$4))*7)} -> 0 | K52: {=INDIRECT("Sheet2!L" & 10 + (ROW(K5)-ROW($C$4))*7)} -> 0 | L52: {=INDIRECT("Sheet2!M" & 10 + (ROW(L5)-ROW($C$4))*7)} -> 0 | M52: {=INDIRECT("Sheet2!N" & 10 + (ROW(M5)-ROW($C$4))*7)} -> 0 | N52: {=INDIRECT("Sheet2!o" & 10 + (ROW(N5)-ROW($C$4))*7)} -> 0 | O52: {=INDIRECT("Sheet2!p" & 10 + (ROW(O5)-ROW($C$4))*7)} -> 0
C53: {=INDIRECT("Sheet2!D" & 10 + (ROW(C6)-ROW($C$4))*7)} -> 0 | D53: {=INDIRECT("Sheet2!E" & 10 + (ROW(D6)-ROW($C$4))*7)} -> 0 | E53: {=INDIRECT("Sheet2!F" & 10 + (ROW(E6)-ROW($C$4))*7)} -> 0 | F53: {=INDIRECT("Sheet2!G" & 10 + (ROW(F6)-ROW($C$4))*7)} -> 0 | G53: {=INDIRECT("Sheet2!H" & 10 + (ROW(G6)-ROW($C$4))*7)} -> 0 | H53: {=INDIRECT("Sheet2!I" & 10 + (ROW(H6)-ROW($C$4))*7)} -> 0 | I53: {=INDIRECT("Sheet2!J" & 10 + (ROW(I6)-ROW($C$4))*7)} -> 0 | J53: {=INDIRECT("Sheet2!K" & 10 + (ROW(J6)-ROW($C$4))*7)} -> 0 | K53: {=INDIRECT("Sheet2!L" & 10 + (ROW(K6)-ROW($C$4))*7)} -> 0 | L53: {=INDIRECT("Sheet2!M" & 10 + (ROW(L6)-ROW($C$4))*7)} -> 0 | M53: {=INDIRECT("Sheet2!N" & 10 + (ROW(M6)-ROW($C$4))*7)} -> 0 | N53: {=INDIRECT("Sheet2!o" & 10 + (ROW(N6)-ROW($C$4))*7)} -> 0 | O53: {=INDIRECT("Sheet2!p" & 10 + (ROW(O6)-ROW($C$4))*7)} -> 0
C54: {=INDIRECT("Sheet2!D" & 10 + (ROW(C7)-ROW($C$4))*7)} -> 0 | D54: {=INDIRECT("Sheet2!E" & 10 + (ROW(D7)-ROW($C$4))*7)} -> 0 | E54: {=INDIRECT("Sheet2!F" & 10 + (ROW(E7)-ROW($C$4))*7)} -> 0 | F54: {=INDIRECT("Sheet2!G" & 10 + (ROW(F7)-ROW($C$4))*7)} -> 0 | G54: {=INDIRECT("Sheet2!H" & 10 + (ROW(G7)-ROW($C$4))*7)} -> 0 | H54: {=INDIRECT("Sheet2!I" & 10 + (ROW(H7)-ROW($C$4))*7)} -> 0 | I54: {=INDIRECT("Sheet2!J" & 10 + (ROW(I7)-ROW($C$4))*7)} -> 0 | J54: {=INDIRECT("Sheet2!K" & 10 + (ROW(J7)-ROW($C$4))*7)} -> 0 | K54: {=INDIRECT("Sheet2!L" & 10 + (ROW(K7)-ROW($C$4))*7)} -> 0 | L54: {=INDIRECT("Sheet2!M" & 10 + (ROW(L7)-ROW($C$4))*7)} -> 0 | M54: {=INDIRECT("Sheet2!N" & 10 + (ROW(M7)-ROW($C$4))*7)} -> 0 | N54: {=INDIRECT("Sheet2!o" & 10 + (ROW(N7)-ROW($C$4))*7)} -> 0 | O54: {=INDIRECT("Sheet2!p" & 10 + (ROW(O7)-ROW($C$4))*7)} -> 0
C55: {=INDIRECT("Sheet2!D" & 10 + (ROW(C8)-ROW($C$4))*7)} -> 0 | D55: {=INDIRECT("Sheet2!E" & 10 + (ROW(D8)-ROW($C$4))*7)} -> 0 | E55: {=INDIRECT("Sheet2!F" & 10 + (ROW(E8)-ROW($C$4))*7)} -> 0 | F55: {=INDIRECT("Sheet2!G" & 10 + (ROW(F8)-ROW($C$4))*7)} -> 0 | G55: {=INDIRECT("Sheet2!H" & 10 + (ROW(G8)-ROW($C$4))*7)} -> 0 | H55: {=INDIRECT("Sheet2!I" & 10 + (ROW(H8)-ROW($C$4))*7)} -> 0 | I55: {=INDIRECT("Sheet2!J" & 10 + (ROW(I8)-ROW($C$4))*7)} -> 0 | J55: {=INDIRECT("Sheet2!K" & 10 + (ROW(J8)-ROW($C$4))*7)} -> 0 | K55: {=INDIRECT("Sheet2!L" & 10 + (ROW(K8)-ROW($C$4))*7)} -> 0 | L55: {=INDIRECT("Sheet2!M" & 10 + (ROW(L8)-ROW($C$4))*7)} -> 0 | M55: {=INDIRECT("Sheet2!N" & 10 + (ROW(M8)-ROW($C$4))*7)} -> 0 | N55: {=INDIRECT("Sheet2!o" & 10 + (ROW(N8)-ROW($C$4))*7)} -> 0 | O55: {=INDIRECT("Sheet2!p" & 10 + (ROW(O8)-ROW($C$4))*7)} -> 0
C56: {=INDIRECT("Sheet2!D" & 10 + (ROW(C9)-ROW($C$4))*7)} -> 0 | D56: {=INDIRECT("Sheet2!E" & 10 + (ROW(D9)-ROW($C$4))*7)} -> 0 | E56: {=INDIRECT("Sheet2!F" & 10 + (ROW(E9)-ROW($C$4))*7)} -> 0 | F56: {=INDIRECT("Sheet2!G" & 10 + (ROW(F9)-ROW($C$4))*7)} -> 0 | G56: {=INDIRECT("Sheet2!H" & 10 + (ROW(G9)-ROW($C$4))*7)} -> 0 | H56: {=INDIRECT("Sheet2!I" & 10 + (ROW(H9)-ROW($C$4))*7)} -> 0 | I56: {=INDIRECT("Sheet2!J" & 10 + (ROW(I9)-ROW($C$4))*7)} -> 0 | J56: {=INDIRECT("Sheet2!K" & 10 + (ROW(J9)-ROW($C$4))*7)} -> 0 | K56: {=INDIRECT("Sheet2!L" & 10 + (ROW(K9)-ROW($C$4))*7)} -> 0 | L56: {=INDIRECT("Sheet2!M" & 10 + (ROW(L9)-ROW($C$4))*7)} -> 0 | M56: {=INDIRECT("Sheet2!N" & 10 + (ROW(M9)-ROW($C$4))*7)} -> 0 | N56: {=INDIRECT("Sheet2!o" & 10 + (ROW(N9)-ROW($C$4))*7)} -> 0 | O56: {=INDIRECT("Sheet2!p" & 10 + (ROW(O9)-ROW($C$4))*7)} -> 0
C57: {=INDIRECT("Sheet2!D" & 10 + (ROW(C10)-ROW($C$4))*7)} -> 0 | D57: {=INDIRECT("Sheet2!E" & 10 + (ROW(D10)-ROW($C$4))*7)} -> 0 | E57: {=INDIRECT("Sheet2!F" & 10 + (ROW(E10)-ROW($C$4))*7)} -> 0 | F57: {=INDIRECT("Sheet2!G" & 10 + (ROW(F10)-ROW($C$4))*7)} -> 0 | G57: {=INDIRECT("Sheet2!H" & 10 + (ROW(G10)-ROW($C$4))*7)} -> 0 | H57: {=INDIRECT("Sheet2!I" & 10 + (ROW(H10)-ROW($C$4))*7)} -> 0 | I57: {=INDIRECT("Sheet2!J" & 10 + (ROW(I10)-ROW($C$4))*7)} -> 0 | J57: {=INDIRECT("Sheet2!K" & 10 + (ROW(J10)-ROW($C$4))*7)} -> 0 | K57: {=INDIRECT("Sheet2!L" & 10 + (ROW(K10)-ROW($C$4))*7)} -> 0 | L57: {=INDIRECT("Sheet2!M" & 10 + (ROW(L10)-ROW($C$4))*7)} -> 0 | M57: {=INDIRECT("Sheet2!N" & 10 + (ROW(M10)-ROW($C$4))*7)} -> 0 | N57: {=INDIRECT("Sheet2!o" & 10 + (ROW(N10)-ROW($C$4))*7)} -> 0 | O57: {=INDIRECT("Sheet2!p" & 10 + (ROW(O10)-ROW($C$4))*7)} -> 0
C58: {=INDIRECT("Sheet2!D" & 10 + (ROW(C11)-ROW($C$4))*7)} -> 0 | D58: {=INDIRECT("Sheet2!E" & 10 + (ROW(D11)-ROW($C$4))*7)} -> 0 | E58: {=INDIRECT("Sheet2!F" & 10 + (ROW(E11)-ROW($C$4))*7)} -> 0 | F58: {=INDIRECT("Sheet2!G" & 10 + (ROW(F11)-ROW($C$4))*7)} -> 0 | G58: {=INDIRECT("Sheet2!H" & 10 + (ROW(G11)-ROW($C$4))*7)} -> 0 | H58: {=INDIRECT("Sheet2!I" & 10 + (ROW(H11)-ROW($C$4))*7)} -> 0 | I58: {=INDIRECT("Sheet2!J" & 10 + (ROW(I11)-ROW($C$4))*7)} -> 0 | J58: {=INDIRECT("Sheet2!K" & 10 + (ROW(J11)-ROW($C$4))*7)} -> 0 | K58: {=INDIRECT("Sheet2!L" & 10 + (ROW(K11)-ROW($C$4))*7)} -> 0 | L58: {=INDIRECT("Sheet2!M" & 10 + (ROW(L11)-ROW($C$4))*7)} -> 0 | M58: {=INDIRECT("Sheet2!N" & 10 + (ROW(M11)-ROW($C$4))*7)} -> 0 | N58: {=INDIRECT("Sheet2!o" & 10 + (ROW(N11)-ROW($C$4))*7)} -> 0 | O58: {=INDIRECT("Sheet2!p" & 10 + (ROW(O11)-ROW($C$4))*7)} -> 0
C59: {=INDIRECT("Sheet2!D" & 10 + (ROW(C12)-ROW($C$4))*7)} -> 0 | D59: {=INDIRECT("Sheet2!E" & 10 + (ROW(D12)-ROW($C$4))*7)} -> 0 | E59: {=INDIRECT("Sheet2!F" & 10 + (ROW(E12)-ROW($C$4))*7)} -> 0 | F59: {=INDIRECT("Sheet2!G" & 10 + (ROW(F12)-ROW($C$4))*7)} -> 0 | G59: {=INDIRECT("Sheet2!H" & 10 + (ROW(G12)-ROW($C$4))*7)} -> 0 | H59: {=INDIRECT("Sheet2!I" & 10 + (ROW(H12)-ROW($C$4))*7)} -> 0 | I59: {=INDIRECT("Sheet2!J" & 10 + (ROW(I12)-ROW($C$4))*7)} -> 0 | J59: {=INDIRECT("Sheet2!K" & 10 + (ROW(J12)-ROW($C$4))*7)} -> 0 | K59: {=INDIRECT("Sheet2!L" & 10 + (ROW(K12)-ROW($C$4))*7)} -> 0 | L59: {=INDIRECT("Sheet2!M" & 10 + (ROW(L12)-ROW($C$4))*7)} -> 0 | M59: {=INDIRECT("Sheet2!N" & 10 + (ROW(M12)-ROW($C$4))*7)} -> 0 | N59: {=INDIRECT("Sheet2!o" & 10 + (ROW(N12)-ROW($C$4))*7)} -> 0 | O59: {=INDIRECT("Sheet2!p" & 10 + (ROW(O12)-ROW($C$4))*7)} -> 0
C60: {=INDIRECT("Sheet2!D" & 10 + (ROW(C13)-ROW($C$4))*7)} -> 0 | D60: {=INDIRECT("Sheet2!E" & 10 + (ROW(D13)-ROW($C$4))*7)} -> 0 | E60: {=INDIRECT("Sheet2!F" & 10 + (ROW(E13)-ROW($C$4))*7)} -> 0 | F60: {=INDIRECT("Sheet2!G" & 10 + (ROW(F13)-ROW($C$4))*7)} -> 0 | G60: {=INDIRECT("Sheet2!H" & 10 + (ROW(G13)-ROW($C$4))*7)} -> 0 | H60: {=INDIRECT("Sheet2!I" & 10 + (ROW(H13)-ROW($C$4))*7)} -> 0 | I60: {=INDIRECT("Sheet2!J" & 10 + (ROW(I13)-ROW($C$4))*7)} -> 0 | J60: {=INDIRECT("Sheet2!K" & 10 + (ROW(J13)-ROW($C$4))*7)} -> 0 | K60: {=INDIRECT("Sheet2!L" & 10 + (ROW(K13)-ROW($C$4))*7)} -> 0 | L60: {=INDIRECT("Sheet2!M" & 10 + (ROW(L13)-ROW($C$4))*7)} -> 0 | M60: {=INDIRECT("Sheet2!N" & 10 + (ROW(M13)-ROW($C$4))*7)} -> 0 | N60: {=INDIRECT("Sheet2!o" & 10 + (ROW(N13)-ROW($C$4))*7)} -> 0 | O60: {=INDIRECT("Sheet2!p" & 10 + (ROW(O13)-ROW($C$4))*7)} -> 0
C61: {=INDIRECT("Sheet2!D" & 10 + (ROW(C14)-ROW($C$4))*7)} -> 0 | D61: {=INDIRECT("Sheet2!E" & 10 + (ROW(D14)-ROW($C$4))*7)} -> 0 | E61: {=INDIRECT("Sheet2!F" & 10 + (ROW(E14)-ROW($C$4))*7)} -> 0 | F61: {=INDIRECT("Sheet2!G" & 10 + (ROW(F14)-ROW($C$4))*7)} -> 0 | G61: {=INDIRECT("Sheet2!H" & 10 + (ROW(G14)-ROW($C$4))*7)} -> 0 | H61: {=INDIRECT("Sheet2!I" & 10 + (ROW(H14)-ROW($C$4))*7)} -> 0 | I61: {=INDIRECT("Sheet2!J" & 10 + (ROW(I14)-ROW($C$4))*7)} -> 0 | J61: {=INDIRECT("Sheet2!K" & 10 + (ROW(J14)-ROW($C$4))*7)} -> 0 | K61: {=INDIRECT("Sheet2!L" & 10 + (ROW(K14)-ROW($C$4))*7)} -> 0 | L61: {=INDIRECT("Sheet2!M" & 10 + (ROW(L14)-ROW($C$4))*7)} -> 0 | M61: {=INDIRECT("Sheet2!N" & 10 + (ROW(M14)-ROW($C$4))*7)} -> 0 | N61: {=INDIRECT("Sheet2!o" & 10 + (ROW(N14)-ROW($C$4))*7)} -> 0 | O61: {=INDIRECT("Sheet2!p" & 10 + (ROW(O14)-ROW($C$4))*7)} -> 0
C62: {=INDIRECT("Sheet2!D" & 10 + (ROW(C15)-ROW($C$4))*7)} -> 0 | D62: {=INDIRECT("Sheet2!E" & 10 + (ROW(D15)-ROW($C$4))*7)} -> 0 | E62: {=INDIRECT("Sheet2!F" & 10 + (ROW(E15)-ROW($C$4))*7)} -> 0 | F62: {=INDIRECT("Sheet2!G" & 10 + (ROW(F15)-ROW($C$4))*7)} -> 0 | G62: {=INDIRECT("Sheet2!H" & 10 + (ROW(G15)-ROW($C$4))*7)} -> 0 | H62: {=INDIRECT("Sheet2!I" & 10 + (ROW(H15)-ROW($C$4))*7)} -> 0 | I62: {=INDIRECT("Sheet2!J" & 10 + (ROW(I15)-ROW($C$4))*7)} -> 0 | J62: {=INDIRECT("Sheet2!K" & 10 + (ROW(J15)-ROW($C$4))*7)} -> 0 | K62: {=INDIRECT("Sheet2!L" & 10 + (ROW(K15)-ROW($C$4))*7)} -> 0 | L62: {=INDIRECT("Sheet2!M" & 10 + (ROW(L15)-ROW($C$4))*7)} -> 0 | M62: {=INDIRECT("Sheet2!N" & 10 + (ROW(M15)-ROW($C$4))*7)} -> 0 | N62: {=INDIRECT("Sheet2!o" & 10 + (ROW(N15)-ROW($C$4))*7)} -> 0 | O62: {=INDIRECT("Sheet2!p" & 10 + (ROW(O15)-ROW($C$4))*7)} -> 0
... C88: {=INDIRECT("Sheet2!D" & 10 + (ROW(C41)-ROW($C$4))*7)} -> 0 | D88: {=INDIRECT("Sheet2!E" & 10 + (ROW(D41)-ROW($C$4))*7)} -> 0 | E88: {=INDIRECT("Sheet2!F" & 10 + (ROW(E41)-ROW($C$4))*7)} -> 0 | F88: {=INDIRECT("Sheet2!G" & 10 + (ROW(F41)-ROW($C$4))*7)} -> 0 | G88: {=INDIRECT("Sheet2!H" & 10 + (ROW(G41)-ROW($C$4))*7)} -> 0 | H88: {=INDIRECT("Sheet2!I" & 10 + (ROW(H41)-ROW($C$4))*7)} -> 0 | I88: {=INDIRECT("Sheet2!J" & 10 + (ROW(I41)-ROW($C$4))*7)} -> 0 | J88: {=INDIRECT("Sheet2!K" & 10 + (ROW(J41)-ROW($C$4))*7)} -> 0 | K88: {=INDIRECT("Sheet2!L" & 10 + (ROW(K41)-ROW($C$4))*7)} -> 0 | L88: {=INDIRECT("Sheet2!M" & 10 + (ROW(L41)-ROW($C$4))*7)} -> 0 | M88: {=INDIRECT("Sheet2!N" & 10 + (ROW(M41)-ROW($C$4))*7)} -> 0 | N88: {=INDIRECT("Sheet2!o" & 10 + (ROW(N41)-ROW($C$4))*7)} -> 0 | O88: {=INDIRECT("Sheet2!p" & 10 + (ROW(O41)-ROW($C$4))*7)} -> 0
B89: Total | C89: =SUM(C51:C88) -> 0 | D89: =SUM(D51:D88) -> 0 | E89: =SUM(E51:E88) -> 0 | F89: =SUM(F51:F88) -> 0 | G89: =SUM(G51:G88) -> 0 | H89: =SUM(H51:H88) -> 0 | I89: =SUM(I51:I88) -> 0 | J89: =SUM(J51:J88) -> 0 | ... O89: =SUM(O51:O88) -> 0
B93: EX CS
